[2023-02-10 14:28:52,058] {taskinstance.py:1159} INFO - Dependencies all met for <TaskInstance: dados_climaticos.extrai_dados scheduled__2023-01-23T00:00:00+00:00 [queued]>
[2023-02-10 14:28:52,060] {taskinstance.py:1159} INFO - Dependencies all met for <TaskInstance: dados_climaticos.extrai_dados scheduled__2023-01-23T00:00:00+00:00 [queued]>
[2023-02-10 14:28:52,060] {taskinstance.py:1356} INFO - 
--------------------------------------------------------------------------------
[2023-02-10 14:28:52,060] {taskinstance.py:1357} INFO - Starting attempt 1 of 1
[2023-02-10 14:28:52,060] {taskinstance.py:1358} INFO - 
--------------------------------------------------------------------------------
[2023-02-10 14:28:52,064] {taskinstance.py:1377} INFO - Executing <Task(PythonOperator): extrai_dados> on 2023-01-23 00:00:00+00:00
[2023-02-10 14:28:52,067] {standard_task_runner.py:52} INFO - Started process 34605 to run task
[2023-02-10 14:28:52,069] {standard_task_runner.py:79} INFO - Running: ['airflow', 'tasks', 'run', 'dados_climaticos', 'extrai_dados', 'scheduled__2023-01-23T00:00:00+00:00', '--job-id', '62', '--raw', '--subdir', 'DAGS_FOLDER/dados_climaticos.py', '--cfg-path', '/var/folders/b_/44w2czd50d77jsslrsmc4_sc0000gn/T/tmpg3ggybkd', '--error-file', '/var/folders/b_/44w2czd50d77jsslrsmc4_sc0000gn/T/tmp1weplyo7']
[2023-02-10 14:28:52,070] {standard_task_runner.py:80} INFO - Job 62: Subtask extrai_dados
[2023-02-10 14:28:52,086] {task_command.py:370} INFO - Running <TaskInstance: dados_climaticos.extrai_dados scheduled__2023-01-23T00:00:00+00:00 [running]> on host airdefrancilene.lan
[2023-02-10 14:28:52,095] {taskinstance.py:1889} ERROR - Task failed with exception
Traceback (most recent call last):
  File "/Users/francilenesilva/Documents/data-engineer/apache-airflow/orquestrando-pipeline1/data-pipeline/airflow-alura/venv/lib/python3.10/site-packages/airflow/models/taskinstance.py", line 1451, in _run_raw_task
    self._execute_task_with_callbacks(context, test_mode)
  File "/Users/francilenesilva/Documents/data-engineer/apache-airflow/orquestrando-pipeline1/data-pipeline/airflow-alura/venv/lib/python3.10/site-packages/airflow/models/taskinstance.py", line 1555, in _execute_task_with_callbacks
    task_orig = self.render_templates(context=context)
  File "/Users/francilenesilva/Documents/data-engineer/apache-airflow/orquestrando-pipeline1/data-pipeline/airflow-alura/venv/lib/python3.10/site-packages/airflow/models/taskinstance.py", line 2212, in render_templates
    rendered_task = self.task.render_template_fields(context)
  File "/Users/francilenesilva/Documents/data-engineer/apache-airflow/orquestrando-pipeline1/data-pipeline/airflow-alura/venv/lib/python3.10/site-packages/airflow/models/baseoperator.py", line 1185, in render_template_fields
    self._do_render_template_fields(self, self.template_fields, context, jinja_env, set())
  File "/Users/francilenesilva/Documents/data-engineer/apache-airflow/orquestrando-pipeline1/data-pipeline/airflow-alura/venv/lib/python3.10/site-packages/airflow/utils/session.py", line 71, in wrapper
    return func(*args, session=session, **kwargs)
  File "/Users/francilenesilva/Documents/data-engineer/apache-airflow/orquestrando-pipeline1/data-pipeline/airflow-alura/venv/lib/python3.10/site-packages/airflow/models/abstractoperator.py", line 344, in _do_render_template_fields
    rendered_content = self.render_template(
  File "/Users/francilenesilva/Documents/data-engineer/apache-airflow/orquestrando-pipeline1/data-pipeline/airflow-alura/venv/lib/python3.10/site-packages/airflow/models/abstractoperator.py", line 404, in render_template
    return {key: self.render_template(value, context, jinja_env) for key, value in value.items()}
  File "/Users/francilenesilva/Documents/data-engineer/apache-airflow/orquestrando-pipeline1/data-pipeline/airflow-alura/venv/lib/python3.10/site-packages/airflow/models/abstractoperator.py", line 404, in <dictcomp>
    return {key: self.render_template(value, context, jinja_env) for key, value in value.items()}
  File "/Users/francilenesilva/Documents/data-engineer/apache-airflow/orquestrando-pipeline1/data-pipeline/airflow-alura/venv/lib/python3.10/site-packages/airflow/models/abstractoperator.py", line 387, in render_template
    template = jinja_env.from_string(value)
  File "/Users/francilenesilva/Documents/data-engineer/apache-airflow/orquestrando-pipeline1/data-pipeline/airflow-alura/venv/lib/python3.10/site-packages/jinja2/environment.py", line 941, in from_string
    return cls.from_code(self, self.compile(source), globals, None)
  File "/Users/francilenesilva/Documents/data-engineer/apache-airflow/orquestrando-pipeline1/data-pipeline/airflow-alura/venv/lib/python3.10/site-packages/jinja2/environment.py", line 638, in compile
    self.handle_exception(source=source_hint)
  File "/Users/francilenesilva/Documents/data-engineer/apache-airflow/orquestrando-pipeline1/data-pipeline/airflow-alura/venv/lib/python3.10/site-packages/jinja2/environment.py", line 832, in handle_exception
    reraise(*rewrite_traceback_stack(source=source))
  File "/Users/francilenesilva/Documents/data-engineer/apache-airflow/orquestrando-pipeline1/data-pipeline/airflow-alura/venv/lib/python3.10/site-packages/jinja2/_compat.py", line 28, in reraise
    raise value.with_traceback(tb)
  File "<unknown>", line -1, in template
jinja2.exceptions.TemplateSyntaxError: unexpected char '"' at 29
[2023-02-10 14:28:52,098] {taskinstance.py:1395} INFO - Marking task as FAILED. dag_id=dados_climaticos, task_id=extrai_dados, execution_date=20230123T000000, start_date=20230210T142852, end_date=20230210T142852
[2023-02-10 14:28:52,101] {standard_task_runner.py:92} ERROR - Failed to execute job 62 for task extrai_dados (unexpected char '"' at 29; 34605)
[2023-02-10 14:28:52,131] {local_task_job.py:156} INFO - Task exited with return code 1
[2023-02-10 14:28:52,139] {local_task_job.py:273} INFO - 0 downstream tasks scheduled from follow-on schedule check
[2023-02-10 14:54:43,444] {taskinstance.py:1159} INFO - Dependencies all met for <TaskInstance: dados_climaticos.extrai_dados scheduled__2023-01-23T00:00:00+00:00 [queued]>
[2023-02-10 14:54:43,446] {taskinstance.py:1159} INFO - Dependencies all met for <TaskInstance: dados_climaticos.extrai_dados scheduled__2023-01-23T00:00:00+00:00 [queued]>
[2023-02-10 14:54:43,446] {taskinstance.py:1356} INFO - 
--------------------------------------------------------------------------------
[2023-02-10 14:54:43,446] {taskinstance.py:1357} INFO - Starting attempt 1 of 1
[2023-02-10 14:54:43,446] {taskinstance.py:1358} INFO - 
--------------------------------------------------------------------------------
[2023-02-10 14:54:43,450] {taskinstance.py:1377} INFO - Executing <Task(PythonOperator): extrai_dados> on 2023-01-23 00:00:00+00:00
[2023-02-10 14:54:43,452] {standard_task_runner.py:52} INFO - Started process 38282 to run task
[2023-02-10 14:54:43,454] {standard_task_runner.py:79} INFO - Running: ['airflow', 'tasks', 'run', 'dados_climaticos', 'extrai_dados', 'scheduled__2023-01-23T00:00:00+00:00', '--job-id', '72', '--raw', '--subdir', 'DAGS_FOLDER/dados_climaticos.py', '--cfg-path', '/var/folders/b_/44w2czd50d77jsslrsmc4_sc0000gn/T/tmpitdl67pc', '--error-file', '/var/folders/b_/44w2czd50d77jsslrsmc4_sc0000gn/T/tmpsnykfrya']
[2023-02-10 14:54:43,455] {standard_task_runner.py:80} INFO - Job 72: Subtask extrai_dados
[2023-02-10 14:54:43,471] {task_command.py:370} INFO - Running <TaskInstance: dados_climaticos.extrai_dados scheduled__2023-01-23T00:00:00+00:00 [running]> on host airdefrancilene.lan
[2023-02-10 14:54:43,481] {taskinstance.py:1889} ERROR - Task failed with exception
Traceback (most recent call last):
  File "/Users/francilenesilva/Documents/data-engineer/apache-airflow/orquestrando-pipeline1/data-pipeline/airflow-alura/venv/lib/python3.10/site-packages/airflow/models/taskinstance.py", line 1451, in _run_raw_task
    self._execute_task_with_callbacks(context, test_mode)
  File "/Users/francilenesilva/Documents/data-engineer/apache-airflow/orquestrando-pipeline1/data-pipeline/airflow-alura/venv/lib/python3.10/site-packages/airflow/models/taskinstance.py", line 1555, in _execute_task_with_callbacks
    task_orig = self.render_templates(context=context)
  File "/Users/francilenesilva/Documents/data-engineer/apache-airflow/orquestrando-pipeline1/data-pipeline/airflow-alura/venv/lib/python3.10/site-packages/airflow/models/taskinstance.py", line 2212, in render_templates
    rendered_task = self.task.render_template_fields(context)
  File "/Users/francilenesilva/Documents/data-engineer/apache-airflow/orquestrando-pipeline1/data-pipeline/airflow-alura/venv/lib/python3.10/site-packages/airflow/models/baseoperator.py", line 1185, in render_template_fields
    self._do_render_template_fields(self, self.template_fields, context, jinja_env, set())
  File "/Users/francilenesilva/Documents/data-engineer/apache-airflow/orquestrando-pipeline1/data-pipeline/airflow-alura/venv/lib/python3.10/site-packages/airflow/utils/session.py", line 71, in wrapper
    return func(*args, session=session, **kwargs)
  File "/Users/francilenesilva/Documents/data-engineer/apache-airflow/orquestrando-pipeline1/data-pipeline/airflow-alura/venv/lib/python3.10/site-packages/airflow/models/abstractoperator.py", line 344, in _do_render_template_fields
    rendered_content = self.render_template(
  File "/Users/francilenesilva/Documents/data-engineer/apache-airflow/orquestrando-pipeline1/data-pipeline/airflow-alura/venv/lib/python3.10/site-packages/airflow/models/abstractoperator.py", line 404, in render_template
    return {key: self.render_template(value, context, jinja_env) for key, value in value.items()}
  File "/Users/francilenesilva/Documents/data-engineer/apache-airflow/orquestrando-pipeline1/data-pipeline/airflow-alura/venv/lib/python3.10/site-packages/airflow/models/abstractoperator.py", line 404, in <dictcomp>
    return {key: self.render_template(value, context, jinja_env) for key, value in value.items()}
  File "/Users/francilenesilva/Documents/data-engineer/apache-airflow/orquestrando-pipeline1/data-pipeline/airflow-alura/venv/lib/python3.10/site-packages/airflow/models/abstractoperator.py", line 387, in render_template
    template = jinja_env.from_string(value)
  File "/Users/francilenesilva/Documents/data-engineer/apache-airflow/orquestrando-pipeline1/data-pipeline/airflow-alura/venv/lib/python3.10/site-packages/jinja2/environment.py", line 941, in from_string
    return cls.from_code(self, self.compile(source), globals, None)
  File "/Users/francilenesilva/Documents/data-engineer/apache-airflow/orquestrando-pipeline1/data-pipeline/airflow-alura/venv/lib/python3.10/site-packages/jinja2/environment.py", line 638, in compile
    self.handle_exception(source=source_hint)
  File "/Users/francilenesilva/Documents/data-engineer/apache-airflow/orquestrando-pipeline1/data-pipeline/airflow-alura/venv/lib/python3.10/site-packages/jinja2/environment.py", line 832, in handle_exception
    reraise(*rewrite_traceback_stack(source=source))
  File "/Users/francilenesilva/Documents/data-engineer/apache-airflow/orquestrando-pipeline1/data-pipeline/airflow-alura/venv/lib/python3.10/site-packages/jinja2/_compat.py", line 28, in reraise
    raise value.with_traceback(tb)
  File "<unknown>", line -1, in template
jinja2.exceptions.TemplateSyntaxError: unexpected char '"' at 29
[2023-02-10 14:54:43,483] {taskinstance.py:1395} INFO - Marking task as FAILED. dag_id=dados_climaticos, task_id=extrai_dados, execution_date=20230123T000000, start_date=20230210T145443, end_date=20230210T145443
[2023-02-10 14:54:43,485] {standard_task_runner.py:92} ERROR - Failed to execute job 72 for task extrai_dados (unexpected char '"' at 29; 38282)
[2023-02-10 14:54:43,516] {local_task_job.py:156} INFO - Task exited with return code 1
[2023-02-10 14:54:43,524] {local_task_job.py:273} INFO - 0 downstream tasks scheduled from follow-on schedule check
[2023-02-10 14:58:58,582] {taskinstance.py:1159} INFO - Dependencies all met for <TaskInstance: dados_climaticos.extrai_dados scheduled__2023-01-23T00:00:00+00:00 [queued]>
[2023-02-10 14:58:58,584] {taskinstance.py:1159} INFO - Dependencies all met for <TaskInstance: dados_climaticos.extrai_dados scheduled__2023-01-23T00:00:00+00:00 [queued]>
[2023-02-10 14:58:58,584] {taskinstance.py:1356} INFO - 
--------------------------------------------------------------------------------
[2023-02-10 14:58:58,584] {taskinstance.py:1357} INFO - Starting attempt 1 of 1
[2023-02-10 14:58:58,584] {taskinstance.py:1358} INFO - 
--------------------------------------------------------------------------------
[2023-02-10 14:58:58,588] {taskinstance.py:1377} INFO - Executing <Task(PythonOperator): extrai_dados> on 2023-01-23 00:00:00+00:00
[2023-02-10 14:58:58,590] {standard_task_runner.py:52} INFO - Started process 38913 to run task
[2023-02-10 14:58:58,592] {standard_task_runner.py:79} INFO - Running: ['airflow', 'tasks', 'run', 'dados_climaticos', 'extrai_dados', 'scheduled__2023-01-23T00:00:00+00:00', '--job-id', '74', '--raw', '--subdir', 'DAGS_FOLDER/dados_climaticos.py', '--cfg-path', '/var/folders/b_/44w2czd50d77jsslrsmc4_sc0000gn/T/tmpa_pa4wzt', '--error-file', '/var/folders/b_/44w2czd50d77jsslrsmc4_sc0000gn/T/tmpce6muc8e']
[2023-02-10 14:58:58,593] {standard_task_runner.py:80} INFO - Job 74: Subtask extrai_dados
[2023-02-10 14:58:58,608] {task_command.py:370} INFO - Running <TaskInstance: dados_climaticos.extrai_dados scheduled__2023-01-23T00:00:00+00:00 [running]> on host airdefrancilene.lan
[2023-02-10 14:58:58,623] {taskinstance.py:1569} INFO - Exporting the following env vars:
AIRFLOW_CTX_DAG_OWNER=airflow
AIRFLOW_CTX_DAG_ID=dados_climaticos
AIRFLOW_CTX_TASK_ID=extrai_dados
AIRFLOW_CTX_EXECUTION_DATE=2023-01-23T00:00:00+00:00
AIRFLOW_CTX_TRY_NUMBER=1
AIRFLOW_CTX_DAG_RUN_ID=scheduled__2023-01-23T00:00:00+00:00
[2023-02-10 14:58:58,624] {taskinstance.py:1889} ERROR - Task failed with exception
Traceback (most recent call last):
  File "/Users/francilenesilva/Documents/data-engineer/apache-airflow/orquestrando-pipeline1/data-pipeline/airflow-alura/venv/lib/python3.10/site-packages/airflow/operators/python.py", line 171, in execute
    return_value = self.execute_callable()
  File "/Users/francilenesilva/Documents/data-engineer/apache-airflow/orquestrando-pipeline1/data-pipeline/airflow-alura/venv/lib/python3.10/site-packages/airflow/operators/python.py", line 189, in execute_callable
    return self.python_callable(*self.op_args, **self.op_kwargs)
  File "/Users/francilenesilva/Documents/data-engineer/apache-airflow/orquestrando-pipeline1/data-pipeline/airflow-alura/dags/dados_climaticos.py", line 33, in extrai_dados
    f'{city}/{data_interval_end}/{ds_add(data_interval_end, 7)}?unitGroup=metric&include=days&key={key}&contentType=csv')
  File "/Users/francilenesilva/Documents/data-engineer/apache-airflow/orquestrando-pipeline1/data-pipeline/airflow-alura/venv/lib/python3.10/site-packages/airflow/macros/__init__.py", line 44, in ds_add
    dt = datetime.strptime(str(ds), "%Y-%m-%d") + timedelta(days=days)
  File "/opt/homebrew/Cellar/python@3.10/3.10.9/Frameworks/Python.framework/Versions/3.10/lib/python3.10/_strptime.py", line 568, in _strptime_datetime
    tt, fraction, gmtoff_fraction = _strptime(data_string, format)
  File "/opt/homebrew/Cellar/python@3.10/3.10.9/Frameworks/Python.framework/Versions/3.10/lib/python3.10/_strptime.py", line 352, in _strptime
    raise ValueError("unconverted data remains: %s" %
ValueError: unconverted data remains: T00:00:00+00:00
[2023-02-10 14:58:58,626] {taskinstance.py:1395} INFO - Marking task as FAILED. dag_id=dados_climaticos, task_id=extrai_dados, execution_date=20230123T000000, start_date=20230210T145858, end_date=20230210T145858
[2023-02-10 14:58:58,629] {standard_task_runner.py:92} ERROR - Failed to execute job 74 for task extrai_dados (unconverted data remains: T00:00:00+00:00; 38913)
[2023-02-10 14:58:58,654] {local_task_job.py:156} INFO - Task exited with return code 1
[2023-02-10 14:58:58,662] {local_task_job.py:273} INFO - 0 downstream tasks scheduled from follow-on schedule check
[2023-02-10 17:29:30,927] {taskinstance.py:1159} INFO - Dependencies all met for <TaskInstance: dados_climaticos.extrai_dados scheduled__2023-01-23T00:00:00+00:00 [queued]>
[2023-02-10 17:29:30,930] {taskinstance.py:1159} INFO - Dependencies all met for <TaskInstance: dados_climaticos.extrai_dados scheduled__2023-01-23T00:00:00+00:00 [queued]>
[2023-02-10 17:29:30,930] {taskinstance.py:1356} INFO - 
--------------------------------------------------------------------------------
[2023-02-10 17:29:30,930] {taskinstance.py:1357} INFO - Starting attempt 1 of 1
[2023-02-10 17:29:30,930] {taskinstance.py:1358} INFO - 
--------------------------------------------------------------------------------
[2023-02-10 17:29:30,933] {taskinstance.py:1377} INFO - Executing <Task(PythonOperator): extrai_dados> on 2023-01-23 00:00:00+00:00
[2023-02-10 17:29:30,935] {standard_task_runner.py:52} INFO - Started process 55381 to run task
[2023-02-10 17:29:30,938] {standard_task_runner.py:79} INFO - Running: ['airflow', 'tasks', 'run', 'dados_climaticos', 'extrai_dados', 'scheduled__2023-01-23T00:00:00+00:00', '--job-id', '112', '--raw', '--subdir', 'DAGS_FOLDER/dados_climaticos.py', '--cfg-path', '/var/folders/b_/44w2czd50d77jsslrsmc4_sc0000gn/T/tmp6kbs8rqp', '--error-file', '/var/folders/b_/44w2czd50d77jsslrsmc4_sc0000gn/T/tmpca0jeq17']
[2023-02-10 17:29:30,938] {standard_task_runner.py:80} INFO - Job 112: Subtask extrai_dados
[2023-02-10 17:29:30,956] {task_command.py:370} INFO - Running <TaskInstance: dados_climaticos.extrai_dados scheduled__2023-01-23T00:00:00+00:00 [running]> on host airdefrancilene.lan
[2023-02-10 17:29:30,981] {taskinstance.py:1569} INFO - Exporting the following env vars:
AIRFLOW_CTX_DAG_OWNER=airflow
AIRFLOW_CTX_DAG_ID=dados_climaticos
AIRFLOW_CTX_TASK_ID=extrai_dados
AIRFLOW_CTX_EXECUTION_DATE=2023-01-23T00:00:00+00:00
AIRFLOW_CTX_TRY_NUMBER=1
AIRFLOW_CTX_DAG_RUN_ID=scheduled__2023-01-23T00:00:00+00:00
[2023-02-10 17:29:31,090] {local_task_job.py:156} INFO - Task exited with return code Negsignal.SIGSEGV
[2023-02-10 17:29:31,095] {taskinstance.py:1395} INFO - Marking task as FAILED. dag_id=dados_climaticos, task_id=extrai_dados, execution_date=20230123T000000, start_date=20230210T172930, end_date=20230210T172931
[2023-02-10 17:29:31,102] {local_task_job.py:273} INFO - 0 downstream tasks scheduled from follow-on schedule check
[2023-02-10 17:33:32,928] {taskinstance.py:1159} INFO - Dependencies all met for <TaskInstance: dados_climaticos.extrai_dados scheduled__2023-01-23T00:00:00+00:00 [queued]>
[2023-02-10 17:33:32,930] {taskinstance.py:1159} INFO - Dependencies all met for <TaskInstance: dados_climaticos.extrai_dados scheduled__2023-01-23T00:00:00+00:00 [queued]>
[2023-02-10 17:33:32,930] {taskinstance.py:1356} INFO - 
--------------------------------------------------------------------------------
[2023-02-10 17:33:32,930] {taskinstance.py:1357} INFO - Starting attempt 1 of 1
[2023-02-10 17:33:32,930] {taskinstance.py:1358} INFO - 
--------------------------------------------------------------------------------
[2023-02-10 17:33:32,934] {taskinstance.py:1377} INFO - Executing <Task(PythonOperator): extrai_dados> on 2023-01-23 00:00:00+00:00
[2023-02-10 17:33:32,936] {standard_task_runner.py:52} INFO - Started process 55958 to run task
[2023-02-10 17:33:32,939] {standard_task_runner.py:79} INFO - Running: ['airflow', 'tasks', 'run', 'dados_climaticos', 'extrai_dados', 'scheduled__2023-01-23T00:00:00+00:00', '--job-id', '128', '--raw', '--subdir', 'DAGS_FOLDER/dados_climaticos.py', '--cfg-path', '/var/folders/b_/44w2czd50d77jsslrsmc4_sc0000gn/T/tmpoa3q0mqq', '--error-file', '/var/folders/b_/44w2czd50d77jsslrsmc4_sc0000gn/T/tmp0_aibgx1']
[2023-02-10 17:33:32,940] {standard_task_runner.py:80} INFO - Job 128: Subtask extrai_dados
[2023-02-10 17:33:32,955] {task_command.py:370} INFO - Running <TaskInstance: dados_climaticos.extrai_dados scheduled__2023-01-23T00:00:00+00:00 [running]> on host airdefrancilene.lan
[2023-02-10 17:33:32,973] {taskinstance.py:1569} INFO - Exporting the following env vars:
AIRFLOW_CTX_DAG_OWNER=airflow
AIRFLOW_CTX_DAG_ID=dados_climaticos
AIRFLOW_CTX_TASK_ID=extrai_dados
AIRFLOW_CTX_EXECUTION_DATE=2023-01-23T00:00:00+00:00
AIRFLOW_CTX_TRY_NUMBER=1
AIRFLOW_CTX_DAG_RUN_ID=scheduled__2023-01-23T00:00:00+00:00
[2023-02-10 17:33:33,090] {local_task_job.py:156} INFO - Task exited with return code Negsignal.SIGSEGV
[2023-02-10 17:33:33,095] {taskinstance.py:1395} INFO - Marking task as FAILED. dag_id=dados_climaticos, task_id=extrai_dados, execution_date=20230123T000000, start_date=20230210T173332, end_date=20230210T173333
[2023-02-10 17:33:33,102] {local_task_job.py:273} INFO - 0 downstream tasks scheduled from follow-on schedule check
[2023-02-10 17:35:54,470] {taskinstance.py:1159} INFO - Dependencies all met for <TaskInstance: dados_climaticos.extrai_dados scheduled__2023-01-23T00:00:00+00:00 [queued]>
[2023-02-10 17:35:54,472] {taskinstance.py:1159} INFO - Dependencies all met for <TaskInstance: dados_climaticos.extrai_dados scheduled__2023-01-23T00:00:00+00:00 [queued]>
[2023-02-10 17:35:54,472] {taskinstance.py:1356} INFO - 
--------------------------------------------------------------------------------
[2023-02-10 17:35:54,472] {taskinstance.py:1357} INFO - Starting attempt 1 of 1
[2023-02-10 17:35:54,472] {taskinstance.py:1358} INFO - 
--------------------------------------------------------------------------------
[2023-02-10 17:35:54,476] {taskinstance.py:1377} INFO - Executing <Task(PythonOperator): extrai_dados> on 2023-01-23 00:00:00+00:00
[2023-02-10 17:35:54,478] {standard_task_runner.py:52} INFO - Started process 56281 to run task
[2023-02-10 17:35:54,480] {standard_task_runner.py:79} INFO - Running: ['airflow', 'tasks', 'run', 'dados_climaticos', 'extrai_dados', 'scheduled__2023-01-23T00:00:00+00:00', '--job-id', '122', '--raw', '--subdir', 'DAGS_FOLDER/dados_climaticos.py', '--cfg-path', '/var/folders/b_/44w2czd50d77jsslrsmc4_sc0000gn/T/tmpajlhc1op', '--error-file', '/var/folders/b_/44w2czd50d77jsslrsmc4_sc0000gn/T/tmpj5b_z49g']
[2023-02-10 17:35:54,481] {standard_task_runner.py:80} INFO - Job 122: Subtask extrai_dados
[2023-02-10 17:35:54,496] {task_command.py:370} INFO - Running <TaskInstance: dados_climaticos.extrai_dados scheduled__2023-01-23T00:00:00+00:00 [running]> on host airdefrancilene.lan
[2023-02-10 17:35:54,514] {taskinstance.py:1569} INFO - Exporting the following env vars:
AIRFLOW_CTX_DAG_OWNER=airflow
AIRFLOW_CTX_DAG_ID=dados_climaticos
AIRFLOW_CTX_TASK_ID=extrai_dados
AIRFLOW_CTX_EXECUTION_DATE=2023-01-23T00:00:00+00:00
AIRFLOW_CTX_TRY_NUMBER=1
AIRFLOW_CTX_DAG_RUN_ID=scheduled__2023-01-23T00:00:00+00:00
[2023-02-10 17:35:54,630] {local_task_job.py:156} INFO - Task exited with return code Negsignal.SIGSEGV
[2023-02-10 17:35:54,636] {taskinstance.py:1395} INFO - Marking task as FAILED. dag_id=dados_climaticos, task_id=extrai_dados, execution_date=20230123T000000, start_date=20230210T173554, end_date=20230210T173554
[2023-02-10 17:35:54,642] {local_task_job.py:273} INFO - 0 downstream tasks scheduled from follow-on schedule check
[2023-02-10 17:46:51,577] {taskinstance.py:1159} INFO - Dependencies all met for <TaskInstance: dados_climaticos.extrai_dados scheduled__2023-01-23T00:00:00+00:00 [queued]>
[2023-02-10 17:46:51,579] {taskinstance.py:1159} INFO - Dependencies all met for <TaskInstance: dados_climaticos.extrai_dados scheduled__2023-01-23T00:00:00+00:00 [queued]>
[2023-02-10 17:46:51,579] {taskinstance.py:1356} INFO - 
--------------------------------------------------------------------------------
[2023-02-10 17:46:51,579] {taskinstance.py:1357} INFO - Starting attempt 1 of 1
[2023-02-10 17:46:51,579] {taskinstance.py:1358} INFO - 
--------------------------------------------------------------------------------
[2023-02-10 17:46:51,583] {taskinstance.py:1377} INFO - Executing <Task(PythonOperator): extrai_dados> on 2023-01-23 00:00:00+00:00
[2023-02-10 17:46:51,585] {standard_task_runner.py:52} INFO - Started process 57690 to run task
[2023-02-10 17:46:51,587] {standard_task_runner.py:79} INFO - Running: ['airflow', 'tasks', 'run', 'dados_climaticos', 'extrai_dados', 'scheduled__2023-01-23T00:00:00+00:00', '--job-id', '124', '--raw', '--subdir', 'DAGS_FOLDER/dados_climaticos.py', '--cfg-path', '/var/folders/b_/44w2czd50d77jsslrsmc4_sc0000gn/T/tmpo3x7p4g_', '--error-file', '/var/folders/b_/44w2czd50d77jsslrsmc4_sc0000gn/T/tmpskl1s_iw']
[2023-02-10 17:46:51,588] {standard_task_runner.py:80} INFO - Job 124: Subtask extrai_dados
[2023-02-10 17:46:51,603] {task_command.py:370} INFO - Running <TaskInstance: dados_climaticos.extrai_dados scheduled__2023-01-23T00:00:00+00:00 [running]> on host airdefrancilene.lan
[2023-02-10 17:46:51,619] {taskinstance.py:1569} INFO - Exporting the following env vars:
AIRFLOW_CTX_DAG_OWNER=airflow
AIRFLOW_CTX_DAG_ID=dados_climaticos
AIRFLOW_CTX_TASK_ID=extrai_dados
AIRFLOW_CTX_EXECUTION_DATE=2023-01-23T00:00:00+00:00
AIRFLOW_CTX_TRY_NUMBER=1
AIRFLOW_CTX_DAG_RUN_ID=scheduled__2023-01-23T00:00:00+00:00
[2023-02-10 17:46:51,738] {local_task_job.py:156} INFO - Task exited with return code Negsignal.SIGSEGV
[2023-02-10 17:46:51,744] {taskinstance.py:1395} INFO - Marking task as FAILED. dag_id=dados_climaticos, task_id=extrai_dados, execution_date=20230123T000000, start_date=20230210T174651, end_date=20230210T174651
[2023-02-10 17:46:51,750] {local_task_job.py:273} INFO - 0 downstream tasks scheduled from follow-on schedule check
[2023-02-10 17:56:13,034] {taskinstance.py:1159} INFO - Dependencies all met for <TaskInstance: dados_climaticos.extrai_dados scheduled__2023-01-23T00:00:00+00:00 [queued]>
[2023-02-10 17:56:13,037] {taskinstance.py:1159} INFO - Dependencies all met for <TaskInstance: dados_climaticos.extrai_dados scheduled__2023-01-23T00:00:00+00:00 [queued]>
[2023-02-10 17:56:13,037] {taskinstance.py:1356} INFO - 
--------------------------------------------------------------------------------
[2023-02-10 17:56:13,037] {taskinstance.py:1357} INFO - Starting attempt 1 of 1
[2023-02-10 17:56:13,037] {taskinstance.py:1358} INFO - 
--------------------------------------------------------------------------------
[2023-02-10 17:56:13,041] {taskinstance.py:1377} INFO - Executing <Task(PythonOperator): extrai_dados> on 2023-01-23 00:00:00+00:00
[2023-02-10 17:56:13,045] {standard_task_runner.py:52} INFO - Started process 59054 to run task
[2023-02-10 17:56:13,047] {standard_task_runner.py:79} INFO - Running: ['airflow', 'tasks', 'run', 'dados_climaticos', 'extrai_dados', 'scheduled__2023-01-23T00:00:00+00:00', '--job-id', '126', '--raw', '--subdir', 'DAGS_FOLDER/dados_climaticos.py', '--cfg-path', '/var/folders/b_/44w2czd50d77jsslrsmc4_sc0000gn/T/tmp8biirdvh', '--error-file', '/var/folders/b_/44w2czd50d77jsslrsmc4_sc0000gn/T/tmpeo3m1e2b']
[2023-02-10 17:56:13,048] {standard_task_runner.py:80} INFO - Job 126: Subtask extrai_dados
[2023-02-10 17:56:13,067] {task_command.py:370} INFO - Running <TaskInstance: dados_climaticos.extrai_dados scheduled__2023-01-23T00:00:00+00:00 [running]> on host airdefrancilene.lan
[2023-02-10 17:56:13,085] {taskinstance.py:1569} INFO - Exporting the following env vars:
AIRFLOW_CTX_DAG_OWNER=airflow
AIRFLOW_CTX_DAG_ID=dados_climaticos
AIRFLOW_CTX_TASK_ID=extrai_dados
AIRFLOW_CTX_EXECUTION_DATE=2023-01-23T00:00:00+00:00
AIRFLOW_CTX_TRY_NUMBER=1
AIRFLOW_CTX_DAG_RUN_ID=scheduled__2023-01-23T00:00:00+00:00
[2023-02-10 17:56:13,104] {taskinstance.py:1889} ERROR - Task failed with exception
Traceback (most recent call last):
  File "/Users/francilenesilva/Documents/data-engineer/apache-airflow/orquestrando-pipeline1/data-pipeline/airflow-alura/venv/lib/python3.10/site-packages/airflow/operators/python.py", line 171, in execute
    return_value = self.execute_callable()
  File "/Users/francilenesilva/Documents/data-engineer/apache-airflow/orquestrando-pipeline1/data-pipeline/airflow-alura/venv/lib/python3.10/site-packages/airflow/operators/python.py", line 189, in execute_callable
    return self.python_callable(*self.op_args, **self.op_kwargs)
  File "/Users/francilenesilva/Documents/data-engineer/apache-airflow/orquestrando-pipeline1/data-pipeline/airflow-alura/dags/dados_climaticos.py", line 31, in extrai_dados
    dados = pd.read_csv(URL)
  File "/Users/francilenesilva/Documents/data-engineer/apache-airflow/orquestrando-pipeline1/data-pipeline/airflow-alura/venv/lib/python3.10/site-packages/pandas/util/_decorators.py", line 211, in wrapper
    return func(*args, **kwargs)
  File "/Users/francilenesilva/Documents/data-engineer/apache-airflow/orquestrando-pipeline1/data-pipeline/airflow-alura/venv/lib/python3.10/site-packages/pandas/util/_decorators.py", line 331, in wrapper
    return func(*args, **kwargs)
  File "/Users/francilenesilva/Documents/data-engineer/apache-airflow/orquestrando-pipeline1/data-pipeline/airflow-alura/venv/lib/python3.10/site-packages/pandas/io/parsers/readers.py", line 950, in read_csv
    return _read(filepath_or_buffer, kwds)
  File "/Users/francilenesilva/Documents/data-engineer/apache-airflow/orquestrando-pipeline1/data-pipeline/airflow-alura/venv/lib/python3.10/site-packages/pandas/io/parsers/readers.py", line 605, in _read
    parser = TextFileReader(filepath_or_buffer, **kwds)
  File "/Users/francilenesilva/Documents/data-engineer/apache-airflow/orquestrando-pipeline1/data-pipeline/airflow-alura/venv/lib/python3.10/site-packages/pandas/io/parsers/readers.py", line 1442, in __init__
    self._engine = self._make_engine(f, self.engine)
  File "/Users/francilenesilva/Documents/data-engineer/apache-airflow/orquestrando-pipeline1/data-pipeline/airflow-alura/venv/lib/python3.10/site-packages/pandas/io/parsers/readers.py", line 1735, in _make_engine
    self.handles = get_handle(
  File "/Users/francilenesilva/Documents/data-engineer/apache-airflow/orquestrando-pipeline1/data-pipeline/airflow-alura/venv/lib/python3.10/site-packages/pandas/io/common.py", line 713, in get_handle
    ioargs = _get_filepath_or_buffer(
  File "/Users/francilenesilva/Documents/data-engineer/apache-airflow/orquestrando-pipeline1/data-pipeline/airflow-alura/venv/lib/python3.10/site-packages/pandas/io/common.py", line 363, in _get_filepath_or_buffer
    with urlopen(req_info) as req:
  File "/Users/francilenesilva/Documents/data-engineer/apache-airflow/orquestrando-pipeline1/data-pipeline/airflow-alura/venv/lib/python3.10/site-packages/pandas/io/common.py", line 265, in urlopen
    return urllib.request.urlopen(*args, **kwargs)
  File "/opt/homebrew/Cellar/python@3.10/3.10.9/Frameworks/Python.framework/Versions/3.10/lib/python3.10/urllib/request.py", line 216, in urlopen
    return opener.open(url, data, timeout)
  File "/opt/homebrew/Cellar/python@3.10/3.10.9/Frameworks/Python.framework/Versions/3.10/lib/python3.10/urllib/request.py", line 519, in open
    response = self._open(req, data)
  File "/opt/homebrew/Cellar/python@3.10/3.10.9/Frameworks/Python.framework/Versions/3.10/lib/python3.10/urllib/request.py", line 536, in _open
    result = self._call_chain(self.handle_open, protocol, protocol +
  File "/opt/homebrew/Cellar/python@3.10/3.10.9/Frameworks/Python.framework/Versions/3.10/lib/python3.10/urllib/request.py", line 496, in _call_chain
    result = func(*args)
  File "/opt/homebrew/Cellar/python@3.10/3.10.9/Frameworks/Python.framework/Versions/3.10/lib/python3.10/urllib/request.py", line 1391, in https_open
    return self.do_open(http.client.HTTPSConnection, req,
  File "/opt/homebrew/Cellar/python@3.10/3.10.9/Frameworks/Python.framework/Versions/3.10/lib/python3.10/urllib/request.py", line 1348, in do_open
    h.request(req.get_method(), req.selector, req.data, headers,
  File "/opt/homebrew/Cellar/python@3.10/3.10.9/Frameworks/Python.framework/Versions/3.10/lib/python3.10/http/client.py", line 1282, in request
    self._send_request(method, url, body, headers, encode_chunked)
  File "/opt/homebrew/Cellar/python@3.10/3.10.9/Frameworks/Python.framework/Versions/3.10/lib/python3.10/http/client.py", line 1293, in _send_request
    self.putrequest(method, url, **skips)
  File "/opt/homebrew/Cellar/python@3.10/3.10.9/Frameworks/Python.framework/Versions/3.10/lib/python3.10/http/client.py", line 1127, in putrequest
    self._validate_path(url)
  File "/opt/homebrew/Cellar/python@3.10/3.10.9/Frameworks/Python.framework/Versions/3.10/lib/python3.10/http/client.py", line 1227, in _validate_path
    raise InvalidURL(f"URL can't contain control characters. {url!r} "
http.client.InvalidURL: URL can't contain control characters. '/VisualCrossingWebServices/rest/services/timeline/{city}/{data_interval_end}/{ds_add(data_interval_end, 7)}?unitGroup=metric&include=days&key={key}&contentType=csv' (found at least ' ')
[2023-02-10 17:56:13,112] {taskinstance.py:1395} INFO - Marking task as FAILED. dag_id=dados_climaticos, task_id=extrai_dados, execution_date=20230123T000000, start_date=20230210T175613, end_date=20230210T175613
[2023-02-10 17:56:13,116] {standard_task_runner.py:92} ERROR - Failed to execute job 126 for task extrai_dados (URL can't contain control characters. '/VisualCrossingWebServices/rest/services/timeline/{city}/{data_interval_end}/{ds_add(data_interval_end, 7)}?unitGroup=metric&include=days&key={key}&contentType=csv' (found at least ' '); 59054)
[2023-02-10 17:56:13,150] {local_task_job.py:156} INFO - Task exited with return code 1
[2023-02-10 17:56:13,159] {local_task_job.py:273} INFO - 0 downstream tasks scheduled from follow-on schedule check
