[2023-02-10 14:28:44,735] {taskinstance.py:1159} INFO - Dependencies all met for <TaskInstance: dados_climaticos.extrai_dados scheduled__2023-01-09T00:00:00+00:00 [queued]>
[2023-02-10 14:28:44,737] {taskinstance.py:1159} INFO - Dependencies all met for <TaskInstance: dados_climaticos.extrai_dados scheduled__2023-01-09T00:00:00+00:00 [queued]>
[2023-02-10 14:28:44,737] {taskinstance.py:1356} INFO - 
--------------------------------------------------------------------------------
[2023-02-10 14:28:44,737] {taskinstance.py:1357} INFO - Starting attempt 1 of 1
[2023-02-10 14:28:44,737] {taskinstance.py:1358} INFO - 
--------------------------------------------------------------------------------
[2023-02-10 14:28:44,741] {taskinstance.py:1377} INFO - Executing <Task(PythonOperator): extrai_dados> on 2023-01-09 00:00:00+00:00
[2023-02-10 14:28:44,743] {standard_task_runner.py:52} INFO - Started process 34573 to run task
[2023-02-10 14:28:44,746] {standard_task_runner.py:79} INFO - Running: ['airflow', 'tasks', 'run', 'dados_climaticos', 'extrai_dados', 'scheduled__2023-01-09T00:00:00+00:00', '--job-id', '57', '--raw', '--subdir', 'DAGS_FOLDER/dados_climaticos.py', '--cfg-path', '/var/folders/b_/44w2czd50d77jsslrsmc4_sc0000gn/T/tmpws8kp3_g', '--error-file', '/var/folders/b_/44w2czd50d77jsslrsmc4_sc0000gn/T/tmpf_crunqk']
[2023-02-10 14:28:44,747] {standard_task_runner.py:80} INFO - Job 57: Subtask extrai_dados
[2023-02-10 14:28:44,762] {task_command.py:370} INFO - Running <TaskInstance: dados_climaticos.extrai_dados scheduled__2023-01-09T00:00:00+00:00 [running]> on host airdefrancilene.lan
[2023-02-10 14:28:44,771] {taskinstance.py:1889} ERROR - Task failed with exception
Traceback (most recent call last):
  File "/Users/francilenesilva/Documents/data-engineer/apache-airflow/orquestrando-pipeline1/data-pipeline/airflow-alura/venv/lib/python3.10/site-packages/airflow/models/taskinstance.py", line 1451, in _run_raw_task
    self._execute_task_with_callbacks(context, test_mode)
  File "/Users/francilenesilva/Documents/data-engineer/apache-airflow/orquestrando-pipeline1/data-pipeline/airflow-alura/venv/lib/python3.10/site-packages/airflow/models/taskinstance.py", line 1555, in _execute_task_with_callbacks
    task_orig = self.render_templates(context=context)
  File "/Users/francilenesilva/Documents/data-engineer/apache-airflow/orquestrando-pipeline1/data-pipeline/airflow-alura/venv/lib/python3.10/site-packages/airflow/models/taskinstance.py", line 2212, in render_templates
    rendered_task = self.task.render_template_fields(context)
  File "/Users/francilenesilva/Documents/data-engineer/apache-airflow/orquestrando-pipeline1/data-pipeline/airflow-alura/venv/lib/python3.10/site-packages/airflow/models/baseoperator.py", line 1185, in render_template_fields
    self._do_render_template_fields(self, self.template_fields, context, jinja_env, set())
  File "/Users/francilenesilva/Documents/data-engineer/apache-airflow/orquestrando-pipeline1/data-pipeline/airflow-alura/venv/lib/python3.10/site-packages/airflow/utils/session.py", line 71, in wrapper
    return func(*args, session=session, **kwargs)
  File "/Users/francilenesilva/Documents/data-engineer/apache-airflow/orquestrando-pipeline1/data-pipeline/airflow-alura/venv/lib/python3.10/site-packages/airflow/models/abstractoperator.py", line 344, in _do_render_template_fields
    rendered_content = self.render_template(
  File "/Users/francilenesilva/Documents/data-engineer/apache-airflow/orquestrando-pipeline1/data-pipeline/airflow-alura/venv/lib/python3.10/site-packages/airflow/models/abstractoperator.py", line 404, in render_template
    return {key: self.render_template(value, context, jinja_env) for key, value in value.items()}
  File "/Users/francilenesilva/Documents/data-engineer/apache-airflow/orquestrando-pipeline1/data-pipeline/airflow-alura/venv/lib/python3.10/site-packages/airflow/models/abstractoperator.py", line 404, in <dictcomp>
    return {key: self.render_template(value, context, jinja_env) for key, value in value.items()}
  File "/Users/francilenesilva/Documents/data-engineer/apache-airflow/orquestrando-pipeline1/data-pipeline/airflow-alura/venv/lib/python3.10/site-packages/airflow/models/abstractoperator.py", line 387, in render_template
    template = jinja_env.from_string(value)
  File "/Users/francilenesilva/Documents/data-engineer/apache-airflow/orquestrando-pipeline1/data-pipeline/airflow-alura/venv/lib/python3.10/site-packages/jinja2/environment.py", line 941, in from_string
    return cls.from_code(self, self.compile(source), globals, None)
  File "/Users/francilenesilva/Documents/data-engineer/apache-airflow/orquestrando-pipeline1/data-pipeline/airflow-alura/venv/lib/python3.10/site-packages/jinja2/environment.py", line 638, in compile
    self.handle_exception(source=source_hint)
  File "/Users/francilenesilva/Documents/data-engineer/apache-airflow/orquestrando-pipeline1/data-pipeline/airflow-alura/venv/lib/python3.10/site-packages/jinja2/environment.py", line 832, in handle_exception
    reraise(*rewrite_traceback_stack(source=source))
  File "/Users/francilenesilva/Documents/data-engineer/apache-airflow/orquestrando-pipeline1/data-pipeline/airflow-alura/venv/lib/python3.10/site-packages/jinja2/_compat.py", line 28, in reraise
    raise value.with_traceback(tb)
  File "<unknown>", line -1, in template
jinja2.exceptions.TemplateSyntaxError: unexpected char '"' at 29
[2023-02-10 14:28:44,773] {taskinstance.py:1395} INFO - Marking task as FAILED. dag_id=dados_climaticos, task_id=extrai_dados, execution_date=20230109T000000, start_date=20230210T142844, end_date=20230210T142844
[2023-02-10 14:28:44,776] {standard_task_runner.py:92} ERROR - Failed to execute job 57 for task extrai_dados (unexpected char '"' at 29; 34573)
[2023-02-10 14:28:44,807] {local_task_job.py:156} INFO - Task exited with return code 1
[2023-02-10 14:28:44,815] {local_task_job.py:273} INFO - 0 downstream tasks scheduled from follow-on schedule check
[2023-02-10 14:54:35,536] {taskinstance.py:1159} INFO - Dependencies all met for <TaskInstance: dados_climaticos.extrai_dados scheduled__2023-01-09T00:00:00+00:00 [queued]>
[2023-02-10 14:54:35,539] {taskinstance.py:1159} INFO - Dependencies all met for <TaskInstance: dados_climaticos.extrai_dados scheduled__2023-01-09T00:00:00+00:00 [queued]>
[2023-02-10 14:54:35,539] {taskinstance.py:1356} INFO - 
--------------------------------------------------------------------------------
[2023-02-10 14:54:35,539] {taskinstance.py:1357} INFO - Starting attempt 1 of 1
[2023-02-10 14:54:35,539] {taskinstance.py:1358} INFO - 
--------------------------------------------------------------------------------
[2023-02-10 14:54:35,542] {taskinstance.py:1377} INFO - Executing <Task(PythonOperator): extrai_dados> on 2023-01-09 00:00:00+00:00
[2023-02-10 14:54:35,544] {standard_task_runner.py:52} INFO - Started process 38227 to run task
[2023-02-10 14:54:35,547] {standard_task_runner.py:79} INFO - Running: ['airflow', 'tasks', 'run', 'dados_climaticos', 'extrai_dados', 'scheduled__2023-01-09T00:00:00+00:00', '--job-id', '67', '--raw', '--subdir', 'DAGS_FOLDER/dados_climaticos.py', '--cfg-path', '/var/folders/b_/44w2czd50d77jsslrsmc4_sc0000gn/T/tmpjl29nrg3', '--error-file', '/var/folders/b_/44w2czd50d77jsslrsmc4_sc0000gn/T/tmp_qad6j8_']
[2023-02-10 14:54:35,548] {standard_task_runner.py:80} INFO - Job 67: Subtask extrai_dados
[2023-02-10 14:54:35,562] {task_command.py:370} INFO - Running <TaskInstance: dados_climaticos.extrai_dados scheduled__2023-01-09T00:00:00+00:00 [running]> on host airdefrancilene.lan
[2023-02-10 14:54:35,571] {taskinstance.py:1889} ERROR - Task failed with exception
Traceback (most recent call last):
  File "/Users/francilenesilva/Documents/data-engineer/apache-airflow/orquestrando-pipeline1/data-pipeline/airflow-alura/venv/lib/python3.10/site-packages/airflow/models/taskinstance.py", line 1451, in _run_raw_task
    self._execute_task_with_callbacks(context, test_mode)
  File "/Users/francilenesilva/Documents/data-engineer/apache-airflow/orquestrando-pipeline1/data-pipeline/airflow-alura/venv/lib/python3.10/site-packages/airflow/models/taskinstance.py", line 1555, in _execute_task_with_callbacks
    task_orig = self.render_templates(context=context)
  File "/Users/francilenesilva/Documents/data-engineer/apache-airflow/orquestrando-pipeline1/data-pipeline/airflow-alura/venv/lib/python3.10/site-packages/airflow/models/taskinstance.py", line 2212, in render_templates
    rendered_task = self.task.render_template_fields(context)
  File "/Users/francilenesilva/Documents/data-engineer/apache-airflow/orquestrando-pipeline1/data-pipeline/airflow-alura/venv/lib/python3.10/site-packages/airflow/models/baseoperator.py", line 1185, in render_template_fields
    self._do_render_template_fields(self, self.template_fields, context, jinja_env, set())
  File "/Users/francilenesilva/Documents/data-engineer/apache-airflow/orquestrando-pipeline1/data-pipeline/airflow-alura/venv/lib/python3.10/site-packages/airflow/utils/session.py", line 71, in wrapper
    return func(*args, session=session, **kwargs)
  File "/Users/francilenesilva/Documents/data-engineer/apache-airflow/orquestrando-pipeline1/data-pipeline/airflow-alura/venv/lib/python3.10/site-packages/airflow/models/abstractoperator.py", line 344, in _do_render_template_fields
    rendered_content = self.render_template(
  File "/Users/francilenesilva/Documents/data-engineer/apache-airflow/orquestrando-pipeline1/data-pipeline/airflow-alura/venv/lib/python3.10/site-packages/airflow/models/abstractoperator.py", line 404, in render_template
    return {key: self.render_template(value, context, jinja_env) for key, value in value.items()}
  File "/Users/francilenesilva/Documents/data-engineer/apache-airflow/orquestrando-pipeline1/data-pipeline/airflow-alura/venv/lib/python3.10/site-packages/airflow/models/abstractoperator.py", line 404, in <dictcomp>
    return {key: self.render_template(value, context, jinja_env) for key, value in value.items()}
  File "/Users/francilenesilva/Documents/data-engineer/apache-airflow/orquestrando-pipeline1/data-pipeline/airflow-alura/venv/lib/python3.10/site-packages/airflow/models/abstractoperator.py", line 387, in render_template
    template = jinja_env.from_string(value)
  File "/Users/francilenesilva/Documents/data-engineer/apache-airflow/orquestrando-pipeline1/data-pipeline/airflow-alura/venv/lib/python3.10/site-packages/jinja2/environment.py", line 941, in from_string
    return cls.from_code(self, self.compile(source), globals, None)
  File "/Users/francilenesilva/Documents/data-engineer/apache-airflow/orquestrando-pipeline1/data-pipeline/airflow-alura/venv/lib/python3.10/site-packages/jinja2/environment.py", line 638, in compile
    self.handle_exception(source=source_hint)
  File "/Users/francilenesilva/Documents/data-engineer/apache-airflow/orquestrando-pipeline1/data-pipeline/airflow-alura/venv/lib/python3.10/site-packages/jinja2/environment.py", line 832, in handle_exception
    reraise(*rewrite_traceback_stack(source=source))
  File "/Users/francilenesilva/Documents/data-engineer/apache-airflow/orquestrando-pipeline1/data-pipeline/airflow-alura/venv/lib/python3.10/site-packages/jinja2/_compat.py", line 28, in reraise
    raise value.with_traceback(tb)
  File "<unknown>", line -1, in template
jinja2.exceptions.TemplateSyntaxError: unexpected char '"' at 29
[2023-02-10 14:54:35,573] {taskinstance.py:1395} INFO - Marking task as FAILED. dag_id=dados_climaticos, task_id=extrai_dados, execution_date=20230109T000000, start_date=20230210T145435, end_date=20230210T145435
[2023-02-10 14:54:35,576] {standard_task_runner.py:92} ERROR - Failed to execute job 67 for task extrai_dados (unexpected char '"' at 29; 38227)
[2023-02-10 14:54:35,578] {local_task_job.py:156} INFO - Task exited with return code 1
[2023-02-10 14:54:35,585] {local_task_job.py:273} INFO - 0 downstream tasks scheduled from follow-on schedule check
[2023-02-10 14:58:50,387] {taskinstance.py:1159} INFO - Dependencies all met for <TaskInstance: dados_climaticos.extrai_dados scheduled__2023-01-09T00:00:00+00:00 [queued]>
[2023-02-10 14:58:50,389] {taskinstance.py:1159} INFO - Dependencies all met for <TaskInstance: dados_climaticos.extrai_dados scheduled__2023-01-09T00:00:00+00:00 [queued]>
[2023-02-10 14:58:50,389] {taskinstance.py:1356} INFO - 
--------------------------------------------------------------------------------
[2023-02-10 14:58:50,389] {taskinstance.py:1357} INFO - Starting attempt 1 of 1
[2023-02-10 14:58:50,389] {taskinstance.py:1358} INFO - 
--------------------------------------------------------------------------------
[2023-02-10 14:58:50,393] {taskinstance.py:1377} INFO - Executing <Task(PythonOperator): extrai_dados> on 2023-01-09 00:00:00+00:00
[2023-02-10 14:58:50,395] {standard_task_runner.py:52} INFO - Started process 38883 to run task
[2023-02-10 14:58:50,397] {standard_task_runner.py:79} INFO - Running: ['airflow', 'tasks', 'run', 'dados_climaticos', 'extrai_dados', 'scheduled__2023-01-09T00:00:00+00:00', '--job-id', '69', '--raw', '--subdir', 'DAGS_FOLDER/dados_climaticos.py', '--cfg-path', '/var/folders/b_/44w2czd50d77jsslrsmc4_sc0000gn/T/tmpd8y8__uz', '--error-file', '/var/folders/b_/44w2czd50d77jsslrsmc4_sc0000gn/T/tmpjmo2pqpd']
[2023-02-10 14:58:50,398] {standard_task_runner.py:80} INFO - Job 69: Subtask extrai_dados
[2023-02-10 14:58:50,414] {task_command.py:370} INFO - Running <TaskInstance: dados_climaticos.extrai_dados scheduled__2023-01-09T00:00:00+00:00 [running]> on host airdefrancilene.lan
[2023-02-10 14:58:50,433] {taskinstance.py:1569} INFO - Exporting the following env vars:
AIRFLOW_CTX_DAG_OWNER=airflow
AIRFLOW_CTX_DAG_ID=dados_climaticos
AIRFLOW_CTX_TASK_ID=extrai_dados
AIRFLOW_CTX_EXECUTION_DATE=2023-01-09T00:00:00+00:00
AIRFLOW_CTX_TRY_NUMBER=1
AIRFLOW_CTX_DAG_RUN_ID=scheduled__2023-01-09T00:00:00+00:00
[2023-02-10 14:58:50,434] {taskinstance.py:1889} ERROR - Task failed with exception
Traceback (most recent call last):
  File "/Users/francilenesilva/Documents/data-engineer/apache-airflow/orquestrando-pipeline1/data-pipeline/airflow-alura/venv/lib/python3.10/site-packages/airflow/operators/python.py", line 171, in execute
    return_value = self.execute_callable()
  File "/Users/francilenesilva/Documents/data-engineer/apache-airflow/orquestrando-pipeline1/data-pipeline/airflow-alura/venv/lib/python3.10/site-packages/airflow/operators/python.py", line 189, in execute_callable
    return self.python_callable(*self.op_args, **self.op_kwargs)
  File "/Users/francilenesilva/Documents/data-engineer/apache-airflow/orquestrando-pipeline1/data-pipeline/airflow-alura/dags/dados_climaticos.py", line 33, in extrai_dados
    f'{city}/{data_interval_end}/{ds_add(data_interval_end, 7)}?unitGroup=metric&include=days&key={key}&contentType=csv')
  File "/Users/francilenesilva/Documents/data-engineer/apache-airflow/orquestrando-pipeline1/data-pipeline/airflow-alura/venv/lib/python3.10/site-packages/airflow/macros/__init__.py", line 44, in ds_add
    dt = datetime.strptime(str(ds), "%Y-%m-%d") + timedelta(days=days)
  File "/opt/homebrew/Cellar/python@3.10/3.10.9/Frameworks/Python.framework/Versions/3.10/lib/python3.10/_strptime.py", line 568, in _strptime_datetime
    tt, fraction, gmtoff_fraction = _strptime(data_string, format)
  File "/opt/homebrew/Cellar/python@3.10/3.10.9/Frameworks/Python.framework/Versions/3.10/lib/python3.10/_strptime.py", line 352, in _strptime
    raise ValueError("unconverted data remains: %s" %
ValueError: unconverted data remains: T00:00:00+00:00
[2023-02-10 14:58:50,436] {taskinstance.py:1395} INFO - Marking task as FAILED. dag_id=dados_climaticos, task_id=extrai_dados, execution_date=20230109T000000, start_date=20230210T145850, end_date=20230210T145850
[2023-02-10 14:58:50,439] {standard_task_runner.py:92} ERROR - Failed to execute job 69 for task extrai_dados (unconverted data remains: T00:00:00+00:00; 38883)
[2023-02-10 14:58:50,460] {local_task_job.py:156} INFO - Task exited with return code 1
[2023-02-10 14:58:50,468] {local_task_job.py:273} INFO - 0 downstream tasks scheduled from follow-on schedule check
[2023-02-10 17:29:23,071] {taskinstance.py:1159} INFO - Dependencies all met for <TaskInstance: dados_climaticos.extrai_dados scheduled__2023-01-09T00:00:00+00:00 [queued]>
[2023-02-10 17:29:23,073] {taskinstance.py:1159} INFO - Dependencies all met for <TaskInstance: dados_climaticos.extrai_dados scheduled__2023-01-09T00:00:00+00:00 [queued]>
[2023-02-10 17:29:23,073] {taskinstance.py:1356} INFO - 
--------------------------------------------------------------------------------
[2023-02-10 17:29:23,074] {taskinstance.py:1357} INFO - Starting attempt 1 of 1
[2023-02-10 17:29:23,074] {taskinstance.py:1358} INFO - 
--------------------------------------------------------------------------------
[2023-02-10 17:29:23,078] {taskinstance.py:1377} INFO - Executing <Task(PythonOperator): extrai_dados> on 2023-01-09 00:00:00+00:00
[2023-02-10 17:29:23,080] {standard_task_runner.py:52} INFO - Started process 55354 to run task
[2023-02-10 17:29:23,082] {standard_task_runner.py:79} INFO - Running: ['airflow', 'tasks', 'run', 'dados_climaticos', 'extrai_dados', 'scheduled__2023-01-09T00:00:00+00:00', '--job-id', '107', '--raw', '--subdir', 'DAGS_FOLDER/dados_climaticos.py', '--cfg-path', '/var/folders/b_/44w2czd50d77jsslrsmc4_sc0000gn/T/tmp7skd620j', '--error-file', '/var/folders/b_/44w2czd50d77jsslrsmc4_sc0000gn/T/tmpg0bcsc68']
[2023-02-10 17:29:23,083] {standard_task_runner.py:80} INFO - Job 107: Subtask extrai_dados
[2023-02-10 17:29:23,100] {task_command.py:370} INFO - Running <TaskInstance: dados_climaticos.extrai_dados scheduled__2023-01-09T00:00:00+00:00 [running]> on host airdefrancilene.lan
[2023-02-10 17:29:23,120] {taskinstance.py:1569} INFO - Exporting the following env vars:
AIRFLOW_CTX_DAG_OWNER=airflow
AIRFLOW_CTX_DAG_ID=dados_climaticos
AIRFLOW_CTX_TASK_ID=extrai_dados
AIRFLOW_CTX_EXECUTION_DATE=2023-01-09T00:00:00+00:00
AIRFLOW_CTX_TRY_NUMBER=1
AIRFLOW_CTX_DAG_RUN_ID=scheduled__2023-01-09T00:00:00+00:00
[2023-02-10 17:29:23,231] {local_task_job.py:156} INFO - Task exited with return code Negsignal.SIGSEGV
[2023-02-10 17:29:23,237] {taskinstance.py:1395} INFO - Marking task as FAILED. dag_id=dados_climaticos, task_id=extrai_dados, execution_date=20230109T000000, start_date=20230210T172923, end_date=20230210T172923
[2023-02-10 17:29:23,243] {local_task_job.py:273} INFO - 0 downstream tasks scheduled from follow-on schedule check
[2023-02-10 17:33:23,863] {taskinstance.py:1159} INFO - Dependencies all met for <TaskInstance: dados_climaticos.extrai_dados scheduled__2023-01-09T00:00:00+00:00 [queued]>
[2023-02-10 17:33:23,865] {taskinstance.py:1159} INFO - Dependencies all met for <TaskInstance: dados_climaticos.extrai_dados scheduled__2023-01-09T00:00:00+00:00 [queued]>
[2023-02-10 17:33:23,865] {taskinstance.py:1356} INFO - 
--------------------------------------------------------------------------------
[2023-02-10 17:33:23,865] {taskinstance.py:1357} INFO - Starting attempt 1 of 1
[2023-02-10 17:33:23,865] {taskinstance.py:1358} INFO - 
--------------------------------------------------------------------------------
[2023-02-10 17:33:23,869] {taskinstance.py:1377} INFO - Executing <Task(PythonOperator): extrai_dados> on 2023-01-09 00:00:00+00:00
[2023-02-10 17:33:23,871] {standard_task_runner.py:52} INFO - Started process 55928 to run task
[2023-02-10 17:33:23,873] {standard_task_runner.py:79} INFO - Running: ['airflow', 'tasks', 'run', 'dados_climaticos', 'extrai_dados', 'scheduled__2023-01-09T00:00:00+00:00', '--job-id', '123', '--raw', '--subdir', 'DAGS_FOLDER/dados_climaticos.py', '--cfg-path', '/var/folders/b_/44w2czd50d77jsslrsmc4_sc0000gn/T/tmp1fje3qa9', '--error-file', '/var/folders/b_/44w2czd50d77jsslrsmc4_sc0000gn/T/tmpk4yamofb']
[2023-02-10 17:33:23,874] {standard_task_runner.py:80} INFO - Job 123: Subtask extrai_dados
[2023-02-10 17:33:23,902] {task_command.py:370} INFO - Running <TaskInstance: dados_climaticos.extrai_dados scheduled__2023-01-09T00:00:00+00:00 [running]> on host airdefrancilene.lan
[2023-02-10 17:33:23,920] {taskinstance.py:1569} INFO - Exporting the following env vars:
AIRFLOW_CTX_DAG_OWNER=airflow
AIRFLOW_CTX_DAG_ID=dados_climaticos
AIRFLOW_CTX_TASK_ID=extrai_dados
AIRFLOW_CTX_EXECUTION_DATE=2023-01-09T00:00:00+00:00
AIRFLOW_CTX_TRY_NUMBER=1
AIRFLOW_CTX_DAG_RUN_ID=scheduled__2023-01-09T00:00:00+00:00
[2023-02-10 17:33:24,025] {local_task_job.py:156} INFO - Task exited with return code Negsignal.SIGSEGV
[2023-02-10 17:33:24,031] {taskinstance.py:1395} INFO - Marking task as FAILED. dag_id=dados_climaticos, task_id=extrai_dados, execution_date=20230109T000000, start_date=20230210T173323, end_date=20230210T173324
[2023-02-10 17:33:24,037] {local_task_job.py:273} INFO - 0 downstream tasks scheduled from follow-on schedule check
