[2023-02-10 14:19:12,803] {taskinstance.py:1159} INFO - Dependencies all met for <TaskInstance: dados_climaticos.cria_pasta scheduled__2022-09-12T00:00:00+00:00 [queued]>
[2023-02-10 14:19:12,805] {taskinstance.py:1159} INFO - Dependencies all met for <TaskInstance: dados_climaticos.cria_pasta scheduled__2022-09-12T00:00:00+00:00 [queued]>
[2023-02-10 14:19:12,805] {taskinstance.py:1356} INFO - 
--------------------------------------------------------------------------------
[2023-02-10 14:19:12,805] {taskinstance.py:1357} INFO - Starting attempt 1 of 1
[2023-02-10 14:19:12,805] {taskinstance.py:1358} INFO - 
--------------------------------------------------------------------------------
[2023-02-10 14:19:12,810] {taskinstance.py:1377} INFO - Executing <Task(BashOperator): cria_pasta> on 2022-09-12 00:00:00+00:00
[2023-02-10 14:19:12,812] {standard_task_runner.py:52} INFO - Started process 33091 to run task
[2023-02-10 14:19:12,815] {standard_task_runner.py:79} INFO - Running: ['airflow', 'tasks', 'run', 'dados_climaticos', 'cria_pasta', 'scheduled__2022-09-12T00:00:00+00:00', '--job-id', '51', '--raw', '--subdir', 'DAGS_FOLDER/dados_climaticos.py', '--cfg-path', '/var/folders/b_/44w2czd50d77jsslrsmc4_sc0000gn/T/tmp_wm_lr0g', '--error-file', '/var/folders/b_/44w2czd50d77jsslrsmc4_sc0000gn/T/tmpqt6feq6l']
[2023-02-10 14:19:12,815] {standard_task_runner.py:80} INFO - Job 51: Subtask cria_pasta
[2023-02-10 14:19:12,834] {task_command.py:370} INFO - Running <TaskInstance: dados_climaticos.cria_pasta scheduled__2022-09-12T00:00:00+00:00 [running]> on host airdefrancilene.lan
[2023-02-10 14:19:12,855] {taskinstance.py:1889} ERROR - Task failed with exception
Traceback (most recent call last):
  File "/Users/francilenesilva/Documents/data-engineer/apache-airflow/orquestrando-pipeline1/data-pipeline/airflow-alura/venv/lib/python3.10/site-packages/airflow/models/taskinstance.py", line 1451, in _run_raw_task
    self._execute_task_with_callbacks(context, test_mode)
  File "/Users/francilenesilva/Documents/data-engineer/apache-airflow/orquestrando-pipeline1/data-pipeline/airflow-alura/venv/lib/python3.10/site-packages/airflow/models/taskinstance.py", line 1555, in _execute_task_with_callbacks
    task_orig = self.render_templates(context=context)
  File "/Users/francilenesilva/Documents/data-engineer/apache-airflow/orquestrando-pipeline1/data-pipeline/airflow-alura/venv/lib/python3.10/site-packages/airflow/models/taskinstance.py", line 2212, in render_templates
    rendered_task = self.task.render_template_fields(context)
  File "/Users/francilenesilva/Documents/data-engineer/apache-airflow/orquestrando-pipeline1/data-pipeline/airflow-alura/venv/lib/python3.10/site-packages/airflow/models/baseoperator.py", line 1185, in render_template_fields
    self._do_render_template_fields(self, self.template_fields, context, jinja_env, set())
  File "/Users/francilenesilva/Documents/data-engineer/apache-airflow/orquestrando-pipeline1/data-pipeline/airflow-alura/venv/lib/python3.10/site-packages/airflow/utils/session.py", line 71, in wrapper
    return func(*args, session=session, **kwargs)
  File "/Users/francilenesilva/Documents/data-engineer/apache-airflow/orquestrando-pipeline1/data-pipeline/airflow-alura/venv/lib/python3.10/site-packages/airflow/models/abstractoperator.py", line 344, in _do_render_template_fields
    rendered_content = self.render_template(
  File "/Users/francilenesilva/Documents/data-engineer/apache-airflow/orquestrando-pipeline1/data-pipeline/airflow-alura/venv/lib/python3.10/site-packages/airflow/models/abstractoperator.py", line 387, in render_template
    template = jinja_env.from_string(value)
  File "/Users/francilenesilva/Documents/data-engineer/apache-airflow/orquestrando-pipeline1/data-pipeline/airflow-alura/venv/lib/python3.10/site-packages/jinja2/environment.py", line 941, in from_string
    return cls.from_code(self, self.compile(source), globals, None)
  File "/Users/francilenesilva/Documents/data-engineer/apache-airflow/orquestrando-pipeline1/data-pipeline/airflow-alura/venv/lib/python3.10/site-packages/jinja2/environment.py", line 638, in compile
    self.handle_exception(source=source_hint)
  File "/Users/francilenesilva/Documents/data-engineer/apache-airflow/orquestrando-pipeline1/data-pipeline/airflow-alura/venv/lib/python3.10/site-packages/jinja2/environment.py", line 832, in handle_exception
    reraise(*rewrite_traceback_stack(source=source))
  File "/Users/francilenesilva/Documents/data-engineer/apache-airflow/orquestrando-pipeline1/data-pipeline/airflow-alura/venv/lib/python3.10/site-packages/jinja2/_compat.py", line 28, in reraise
    raise value.with_traceback(tb)
  File "<unknown>", line -1, in template
jinja2.exceptions.TemplateSyntaxError: unexpected end of template, expected ','.
[2023-02-10 14:19:12,858] {taskinstance.py:1395} INFO - Marking task as FAILED. dag_id=dados_climaticos, task_id=cria_pasta, execution_date=20220912T000000, start_date=20230210T141912, end_date=20230210T141912
[2023-02-10 14:19:12,862] {standard_task_runner.py:92} ERROR - Failed to execute job 51 for task cria_pasta (unexpected end of template, expected ','.; 33091)
[2023-02-10 14:19:12,874] {local_task_job.py:156} INFO - Task exited with return code 1
[2023-02-10 14:19:12,888] {local_task_job.py:273} INFO - 0 downstream tasks scheduled from follow-on schedule check
[2023-02-10 14:22:50,056] {taskinstance.py:1159} INFO - Dependencies all met for <TaskInstance: dados_climaticos.cria_pasta scheduled__2022-09-12T00:00:00+00:00 [queued]>
[2023-02-10 14:22:50,058] {taskinstance.py:1159} INFO - Dependencies all met for <TaskInstance: dados_climaticos.cria_pasta scheduled__2022-09-12T00:00:00+00:00 [queued]>
[2023-02-10 14:22:50,058] {taskinstance.py:1356} INFO - 
--------------------------------------------------------------------------------
[2023-02-10 14:22:50,058] {taskinstance.py:1357} INFO - Starting attempt 1 of 1
[2023-02-10 14:22:50,059] {taskinstance.py:1358} INFO - 
--------------------------------------------------------------------------------
[2023-02-10 14:22:50,062] {taskinstance.py:1377} INFO - Executing <Task(BashOperator): cria_pasta> on 2022-09-12 00:00:00+00:00
[2023-02-10 14:22:50,064] {standard_task_runner.py:52} INFO - Started process 33682 to run task
[2023-02-10 14:22:50,066] {standard_task_runner.py:79} INFO - Running: ['airflow', 'tasks', 'run', 'dados_climaticos', 'cria_pasta', 'scheduled__2022-09-12T00:00:00+00:00', '--job-id', '53', '--raw', '--subdir', 'DAGS_FOLDER/dados_climaticos.py', '--cfg-path', '/var/folders/b_/44w2czd50d77jsslrsmc4_sc0000gn/T/tmp5lnrgoip', '--error-file', '/var/folders/b_/44w2czd50d77jsslrsmc4_sc0000gn/T/tmp0iiw7p06']
[2023-02-10 14:22:50,067] {standard_task_runner.py:80} INFO - Job 53: Subtask cria_pasta
[2023-02-10 14:22:50,082] {task_command.py:370} INFO - Running <TaskInstance: dados_climaticos.cria_pasta scheduled__2022-09-12T00:00:00+00:00 [running]> on host airdefrancilene.lan
[2023-02-10 14:22:50,092] {taskinstance.py:1889} ERROR - Task failed with exception
Traceback (most recent call last):
  File "/Users/francilenesilva/Documents/data-engineer/apache-airflow/orquestrando-pipeline1/data-pipeline/airflow-alura/venv/lib/python3.10/site-packages/airflow/models/taskinstance.py", line 1451, in _run_raw_task
    self._execute_task_with_callbacks(context, test_mode)
  File "/Users/francilenesilva/Documents/data-engineer/apache-airflow/orquestrando-pipeline1/data-pipeline/airflow-alura/venv/lib/python3.10/site-packages/airflow/models/taskinstance.py", line 1555, in _execute_task_with_callbacks
    task_orig = self.render_templates(context=context)
  File "/Users/francilenesilva/Documents/data-engineer/apache-airflow/orquestrando-pipeline1/data-pipeline/airflow-alura/venv/lib/python3.10/site-packages/airflow/models/taskinstance.py", line 2212, in render_templates
    rendered_task = self.task.render_template_fields(context)
  File "/Users/francilenesilva/Documents/data-engineer/apache-airflow/orquestrando-pipeline1/data-pipeline/airflow-alura/venv/lib/python3.10/site-packages/airflow/models/baseoperator.py", line 1185, in render_template_fields
    self._do_render_template_fields(self, self.template_fields, context, jinja_env, set())
  File "/Users/francilenesilva/Documents/data-engineer/apache-airflow/orquestrando-pipeline1/data-pipeline/airflow-alura/venv/lib/python3.10/site-packages/airflow/utils/session.py", line 71, in wrapper
    return func(*args, session=session, **kwargs)
  File "/Users/francilenesilva/Documents/data-engineer/apache-airflow/orquestrando-pipeline1/data-pipeline/airflow-alura/venv/lib/python3.10/site-packages/airflow/models/abstractoperator.py", line 344, in _do_render_template_fields
    rendered_content = self.render_template(
  File "/Users/francilenesilva/Documents/data-engineer/apache-airflow/orquestrando-pipeline1/data-pipeline/airflow-alura/venv/lib/python3.10/site-packages/airflow/models/abstractoperator.py", line 387, in render_template
    template = jinja_env.from_string(value)
  File "/Users/francilenesilva/Documents/data-engineer/apache-airflow/orquestrando-pipeline1/data-pipeline/airflow-alura/venv/lib/python3.10/site-packages/jinja2/environment.py", line 941, in from_string
    return cls.from_code(self, self.compile(source), globals, None)
  File "/Users/francilenesilva/Documents/data-engineer/apache-airflow/orquestrando-pipeline1/data-pipeline/airflow-alura/venv/lib/python3.10/site-packages/jinja2/environment.py", line 638, in compile
    self.handle_exception(source=source_hint)
  File "/Users/francilenesilva/Documents/data-engineer/apache-airflow/orquestrando-pipeline1/data-pipeline/airflow-alura/venv/lib/python3.10/site-packages/jinja2/environment.py", line 832, in handle_exception
    reraise(*rewrite_traceback_stack(source=source))
  File "/Users/francilenesilva/Documents/data-engineer/apache-airflow/orquestrando-pipeline1/data-pipeline/airflow-alura/venv/lib/python3.10/site-packages/jinja2/_compat.py", line 28, in reraise
    raise value.with_traceback(tb)
  File "<unknown>", line -1, in template
jinja2.exceptions.TemplateSyntaxError: unexpected end of template, expected ','.
[2023-02-10 14:22:50,094] {taskinstance.py:1395} INFO - Marking task as FAILED. dag_id=dados_climaticos, task_id=cria_pasta, execution_date=20220912T000000, start_date=20230210T142250, end_date=20230210T142250
[2023-02-10 14:22:50,096] {standard_task_runner.py:92} ERROR - Failed to execute job 53 for task cria_pasta (unexpected end of template, expected ','.; 33682)
[2023-02-10 14:22:50,127] {local_task_job.py:156} INFO - Task exited with return code 1
[2023-02-10 14:22:50,137] {local_task_job.py:273} INFO - 0 downstream tasks scheduled from follow-on schedule check
[2023-02-10 17:28:27,746] {taskinstance.py:1159} INFO - Dependencies all met for <TaskInstance: dados_climaticos.cria_pasta scheduled__2022-09-12T00:00:00+00:00 [queued]>
[2023-02-10 17:28:27,749] {taskinstance.py:1159} INFO - Dependencies all met for <TaskInstance: dados_climaticos.cria_pasta scheduled__2022-09-12T00:00:00+00:00 [queued]>
[2023-02-10 17:28:27,749] {taskinstance.py:1356} INFO - 
--------------------------------------------------------------------------------
[2023-02-10 17:28:27,749] {taskinstance.py:1357} INFO - Starting attempt 1 of 1
[2023-02-10 17:28:27,749] {taskinstance.py:1358} INFO - 
--------------------------------------------------------------------------------
[2023-02-10 17:28:27,752] {taskinstance.py:1377} INFO - Executing <Task(BashOperator): cria_pasta> on 2022-09-12 00:00:00+00:00
[2023-02-10 17:28:27,754] {standard_task_runner.py:52} INFO - Started process 55162 to run task
[2023-02-10 17:28:27,757] {standard_task_runner.py:79} INFO - Running: ['airflow', 'tasks', 'run', 'dados_climaticos', 'cria_pasta', 'scheduled__2022-09-12T00:00:00+00:00', '--job-id', '72', '--raw', '--subdir', 'DAGS_FOLDER/dados_climaticos.py', '--cfg-path', '/var/folders/b_/44w2czd50d77jsslrsmc4_sc0000gn/T/tmpnxwc_jn9', '--error-file', '/var/folders/b_/44w2czd50d77jsslrsmc4_sc0000gn/T/tmppikqliad']
[2023-02-10 17:28:27,757] {standard_task_runner.py:80} INFO - Job 72: Subtask cria_pasta
[2023-02-10 17:28:27,780] {task_command.py:370} INFO - Running <TaskInstance: dados_climaticos.cria_pasta scheduled__2022-09-12T00:00:00+00:00 [running]> on host airdefrancilene.lan
[2023-02-10 17:28:27,800] {taskinstance.py:1569} INFO - Exporting the following env vars:
AIRFLOW_CTX_DAG_OWNER=airflow
AIRFLOW_CTX_DAG_ID=dados_climaticos
AIRFLOW_CTX_TASK_ID=cria_pasta
AIRFLOW_CTX_EXECUTION_DATE=2022-09-12T00:00:00+00:00
AIRFLOW_CTX_TRY_NUMBER=1
AIRFLOW_CTX_DAG_RUN_ID=scheduled__2022-09-12T00:00:00+00:00
[2023-02-10 17:28:27,800] {subprocess.py:62} INFO - Tmp dir root location: 
 /var/folders/b_/44w2czd50d77jsslrsmc4_sc0000gn/T
[2023-02-10 17:28:27,801] {subprocess.py:74} INFO - Running command: ['bash', '-c', 'mkdir -p  "/Users/francilenesilva/Documents/data-engineer/apache-airflow/orquestrando-pipeline1/data-pipeline/airflow-alura/semana=2022-09-19"']
[2023-02-10 17:28:27,805] {subprocess.py:85} INFO - Output:
[2023-02-10 17:28:27,809] {subprocess.py:96} INFO - Command exited with return code 0
[2023-02-10 17:28:27,818] {taskinstance.py:1395} INFO - Marking task as SUCCESS. dag_id=dados_climaticos, task_id=cria_pasta, execution_date=20220912T000000, start_date=20230210T172827, end_date=20230210T172827
[2023-02-10 17:28:27,861] {local_task_job.py:156} INFO - Task exited with return code 0
[2023-02-10 17:28:27,871] {local_task_job.py:273} INFO - 1 downstream tasks scheduled from follow-on schedule check
