[2023-02-10 14:19:11,330] {taskinstance.py:1159} INFO - Dependencies all met for <TaskInstance: dados_climaticos.cria_pasta scheduled__2022-09-05T00:00:00+00:00 [queued]>
[2023-02-10 14:19:11,332] {taskinstance.py:1159} INFO - Dependencies all met for <TaskInstance: dados_climaticos.cria_pasta scheduled__2022-09-05T00:00:00+00:00 [queued]>
[2023-02-10 14:19:11,332] {taskinstance.py:1356} INFO - 
--------------------------------------------------------------------------------
[2023-02-10 14:19:11,332] {taskinstance.py:1357} INFO - Starting attempt 1 of 1
[2023-02-10 14:19:11,332] {taskinstance.py:1358} INFO - 
--------------------------------------------------------------------------------
[2023-02-10 14:19:11,335] {taskinstance.py:1377} INFO - Executing <Task(BashOperator): cria_pasta> on 2022-09-05 00:00:00+00:00
[2023-02-10 14:19:11,337] {standard_task_runner.py:52} INFO - Started process 33080 to run task
[2023-02-10 14:19:11,339] {standard_task_runner.py:79} INFO - Running: ['airflow', 'tasks', 'run', 'dados_climaticos', 'cria_pasta', 'scheduled__2022-09-05T00:00:00+00:00', '--job-id', '50', '--raw', '--subdir', 'DAGS_FOLDER/dados_climaticos.py', '--cfg-path', '/var/folders/b_/44w2czd50d77jsslrsmc4_sc0000gn/T/tmp8mkm3gps', '--error-file', '/var/folders/b_/44w2czd50d77jsslrsmc4_sc0000gn/T/tmpgen_1a99']
[2023-02-10 14:19:11,340] {standard_task_runner.py:80} INFO - Job 50: Subtask cria_pasta
[2023-02-10 14:19:11,358] {task_command.py:370} INFO - Running <TaskInstance: dados_climaticos.cria_pasta scheduled__2022-09-05T00:00:00+00:00 [running]> on host airdefrancilene.lan
[2023-02-10 14:19:11,367] {taskinstance.py:1889} ERROR - Task failed with exception
Traceback (most recent call last):
  File "/Users/francilenesilva/Documents/data-engineer/apache-airflow/orquestrando-pipeline1/data-pipeline/airflow-alura/venv/lib/python3.10/site-packages/airflow/models/taskinstance.py", line 1451, in _run_raw_task
    self._execute_task_with_callbacks(context, test_mode)
  File "/Users/francilenesilva/Documents/data-engineer/apache-airflow/orquestrando-pipeline1/data-pipeline/airflow-alura/venv/lib/python3.10/site-packages/airflow/models/taskinstance.py", line 1555, in _execute_task_with_callbacks
    task_orig = self.render_templates(context=context)
  File "/Users/francilenesilva/Documents/data-engineer/apache-airflow/orquestrando-pipeline1/data-pipeline/airflow-alura/venv/lib/python3.10/site-packages/airflow/models/taskinstance.py", line 2212, in render_templates
    rendered_task = self.task.render_template_fields(context)
  File "/Users/francilenesilva/Documents/data-engineer/apache-airflow/orquestrando-pipeline1/data-pipeline/airflow-alura/venv/lib/python3.10/site-packages/airflow/models/baseoperator.py", line 1185, in render_template_fields
    self._do_render_template_fields(self, self.template_fields, context, jinja_env, set())
  File "/Users/francilenesilva/Documents/data-engineer/apache-airflow/orquestrando-pipeline1/data-pipeline/airflow-alura/venv/lib/python3.10/site-packages/airflow/utils/session.py", line 71, in wrapper
    return func(*args, session=session, **kwargs)
  File "/Users/francilenesilva/Documents/data-engineer/apache-airflow/orquestrando-pipeline1/data-pipeline/airflow-alura/venv/lib/python3.10/site-packages/airflow/models/abstractoperator.py", line 344, in _do_render_template_fields
    rendered_content = self.render_template(
  File "/Users/francilenesilva/Documents/data-engineer/apache-airflow/orquestrando-pipeline1/data-pipeline/airflow-alura/venv/lib/python3.10/site-packages/airflow/models/abstractoperator.py", line 387, in render_template
    template = jinja_env.from_string(value)
  File "/Users/francilenesilva/Documents/data-engineer/apache-airflow/orquestrando-pipeline1/data-pipeline/airflow-alura/venv/lib/python3.10/site-packages/jinja2/environment.py", line 941, in from_string
    return cls.from_code(self, self.compile(source), globals, None)
  File "/Users/francilenesilva/Documents/data-engineer/apache-airflow/orquestrando-pipeline1/data-pipeline/airflow-alura/venv/lib/python3.10/site-packages/jinja2/environment.py", line 638, in compile
    self.handle_exception(source=source_hint)
  File "/Users/francilenesilva/Documents/data-engineer/apache-airflow/orquestrando-pipeline1/data-pipeline/airflow-alura/venv/lib/python3.10/site-packages/jinja2/environment.py", line 832, in handle_exception
    reraise(*rewrite_traceback_stack(source=source))
  File "/Users/francilenesilva/Documents/data-engineer/apache-airflow/orquestrando-pipeline1/data-pipeline/airflow-alura/venv/lib/python3.10/site-packages/jinja2/_compat.py", line 28, in reraise
    raise value.with_traceback(tb)
  File "<unknown>", line -1, in template
jinja2.exceptions.TemplateSyntaxError: unexpected end of template, expected ','.
[2023-02-10 14:19:11,370] {taskinstance.py:1395} INFO - Marking task as FAILED. dag_id=dados_climaticos, task_id=cria_pasta, execution_date=20220905T000000, start_date=20230210T141911, end_date=20230210T141911
[2023-02-10 14:19:11,373] {standard_task_runner.py:92} ERROR - Failed to execute job 50 for task cria_pasta (unexpected end of template, expected ','.; 33080)
[2023-02-10 14:19:11,402] {local_task_job.py:156} INFO - Task exited with return code 1
[2023-02-10 14:19:11,413] {local_task_job.py:273} INFO - 0 downstream tasks scheduled from follow-on schedule check
[2023-02-10 14:22:48,621] {taskinstance.py:1159} INFO - Dependencies all met for <TaskInstance: dados_climaticos.cria_pasta scheduled__2022-09-05T00:00:00+00:00 [queued]>
[2023-02-10 14:22:48,623] {taskinstance.py:1159} INFO - Dependencies all met for <TaskInstance: dados_climaticos.cria_pasta scheduled__2022-09-05T00:00:00+00:00 [queued]>
[2023-02-10 14:22:48,623] {taskinstance.py:1356} INFO - 
--------------------------------------------------------------------------------
[2023-02-10 14:22:48,623] {taskinstance.py:1357} INFO - Starting attempt 1 of 1
[2023-02-10 14:22:48,623] {taskinstance.py:1358} INFO - 
--------------------------------------------------------------------------------
[2023-02-10 14:22:48,626] {taskinstance.py:1377} INFO - Executing <Task(BashOperator): cria_pasta> on 2022-09-05 00:00:00+00:00
[2023-02-10 14:22:48,628] {standard_task_runner.py:52} INFO - Started process 33678 to run task
[2023-02-10 14:22:48,631] {standard_task_runner.py:79} INFO - Running: ['airflow', 'tasks', 'run', 'dados_climaticos', 'cria_pasta', 'scheduled__2022-09-05T00:00:00+00:00', '--job-id', '52', '--raw', '--subdir', 'DAGS_FOLDER/dados_climaticos.py', '--cfg-path', '/var/folders/b_/44w2czd50d77jsslrsmc4_sc0000gn/T/tmpl5y5ydbi', '--error-file', '/var/folders/b_/44w2czd50d77jsslrsmc4_sc0000gn/T/tmp98vimhel']
[2023-02-10 14:22:48,631] {standard_task_runner.py:80} INFO - Job 52: Subtask cria_pasta
[2023-02-10 14:22:48,652] {task_command.py:370} INFO - Running <TaskInstance: dados_climaticos.cria_pasta scheduled__2022-09-05T00:00:00+00:00 [running]> on host airdefrancilene.lan
[2023-02-10 14:22:48,662] {taskinstance.py:1889} ERROR - Task failed with exception
Traceback (most recent call last):
  File "/Users/francilenesilva/Documents/data-engineer/apache-airflow/orquestrando-pipeline1/data-pipeline/airflow-alura/venv/lib/python3.10/site-packages/airflow/models/taskinstance.py", line 1451, in _run_raw_task
    self._execute_task_with_callbacks(context, test_mode)
  File "/Users/francilenesilva/Documents/data-engineer/apache-airflow/orquestrando-pipeline1/data-pipeline/airflow-alura/venv/lib/python3.10/site-packages/airflow/models/taskinstance.py", line 1555, in _execute_task_with_callbacks
    task_orig = self.render_templates(context=context)
  File "/Users/francilenesilva/Documents/data-engineer/apache-airflow/orquestrando-pipeline1/data-pipeline/airflow-alura/venv/lib/python3.10/site-packages/airflow/models/taskinstance.py", line 2212, in render_templates
    rendered_task = self.task.render_template_fields(context)
  File "/Users/francilenesilva/Documents/data-engineer/apache-airflow/orquestrando-pipeline1/data-pipeline/airflow-alura/venv/lib/python3.10/site-packages/airflow/models/baseoperator.py", line 1185, in render_template_fields
    self._do_render_template_fields(self, self.template_fields, context, jinja_env, set())
  File "/Users/francilenesilva/Documents/data-engineer/apache-airflow/orquestrando-pipeline1/data-pipeline/airflow-alura/venv/lib/python3.10/site-packages/airflow/utils/session.py", line 71, in wrapper
    return func(*args, session=session, **kwargs)
  File "/Users/francilenesilva/Documents/data-engineer/apache-airflow/orquestrando-pipeline1/data-pipeline/airflow-alura/venv/lib/python3.10/site-packages/airflow/models/abstractoperator.py", line 344, in _do_render_template_fields
    rendered_content = self.render_template(
  File "/Users/francilenesilva/Documents/data-engineer/apache-airflow/orquestrando-pipeline1/data-pipeline/airflow-alura/venv/lib/python3.10/site-packages/airflow/models/abstractoperator.py", line 387, in render_template
    template = jinja_env.from_string(value)
  File "/Users/francilenesilva/Documents/data-engineer/apache-airflow/orquestrando-pipeline1/data-pipeline/airflow-alura/venv/lib/python3.10/site-packages/jinja2/environment.py", line 941, in from_string
    return cls.from_code(self, self.compile(source), globals, None)
  File "/Users/francilenesilva/Documents/data-engineer/apache-airflow/orquestrando-pipeline1/data-pipeline/airflow-alura/venv/lib/python3.10/site-packages/jinja2/environment.py", line 638, in compile
    self.handle_exception(source=source_hint)
  File "/Users/francilenesilva/Documents/data-engineer/apache-airflow/orquestrando-pipeline1/data-pipeline/airflow-alura/venv/lib/python3.10/site-packages/jinja2/environment.py", line 832, in handle_exception
    reraise(*rewrite_traceback_stack(source=source))
  File "/Users/francilenesilva/Documents/data-engineer/apache-airflow/orquestrando-pipeline1/data-pipeline/airflow-alura/venv/lib/python3.10/site-packages/jinja2/_compat.py", line 28, in reraise
    raise value.with_traceback(tb)
  File "<unknown>", line -1, in template
jinja2.exceptions.TemplateSyntaxError: unexpected end of template, expected ','.
[2023-02-10 14:22:48,664] {taskinstance.py:1395} INFO - Marking task as FAILED. dag_id=dados_climaticos, task_id=cria_pasta, execution_date=20220905T000000, start_date=20230210T142248, end_date=20230210T142248
[2023-02-10 14:22:48,667] {standard_task_runner.py:92} ERROR - Failed to execute job 52 for task cria_pasta (unexpected end of template, expected ','.; 33678)
[2023-02-10 14:22:48,690] {local_task_job.py:156} INFO - Task exited with return code 1
[2023-02-10 14:22:48,701] {local_task_job.py:273} INFO - 0 downstream tasks scheduled from follow-on schedule check
[2023-02-10 17:28:22,688] {taskinstance.py:1159} INFO - Dependencies all met for <TaskInstance: dados_climaticos.cria_pasta scheduled__2022-09-05T00:00:00+00:00 [queued]>
[2023-02-10 17:28:22,690] {taskinstance.py:1159} INFO - Dependencies all met for <TaskInstance: dados_climaticos.cria_pasta scheduled__2022-09-05T00:00:00+00:00 [queued]>
[2023-02-10 17:28:22,690] {taskinstance.py:1356} INFO - 
--------------------------------------------------------------------------------
[2023-02-10 17:28:22,690] {taskinstance.py:1357} INFO - Starting attempt 1 of 1
[2023-02-10 17:28:22,690] {taskinstance.py:1358} INFO - 
--------------------------------------------------------------------------------
[2023-02-10 17:28:22,694] {taskinstance.py:1377} INFO - Executing <Task(BashOperator): cria_pasta> on 2022-09-05 00:00:00+00:00
[2023-02-10 17:28:22,696] {standard_task_runner.py:52} INFO - Started process 55145 to run task
[2023-02-10 17:28:22,698] {standard_task_runner.py:79} INFO - Running: ['airflow', 'tasks', 'run', 'dados_climaticos', 'cria_pasta', 'scheduled__2022-09-05T00:00:00+00:00', '--job-id', '69', '--raw', '--subdir', 'DAGS_FOLDER/dados_climaticos.py', '--cfg-path', '/var/folders/b_/44w2czd50d77jsslrsmc4_sc0000gn/T/tmpjdttwx0s', '--error-file', '/var/folders/b_/44w2czd50d77jsslrsmc4_sc0000gn/T/tmpel5hun_x']
[2023-02-10 17:28:22,699] {standard_task_runner.py:80} INFO - Job 69: Subtask cria_pasta
[2023-02-10 17:28:22,714] {task_command.py:370} INFO - Running <TaskInstance: dados_climaticos.cria_pasta scheduled__2022-09-05T00:00:00+00:00 [running]> on host airdefrancilene.lan
[2023-02-10 17:28:22,730] {taskinstance.py:1569} INFO - Exporting the following env vars:
AIRFLOW_CTX_DAG_OWNER=airflow
AIRFLOW_CTX_DAG_ID=dados_climaticos
AIRFLOW_CTX_TASK_ID=cria_pasta
AIRFLOW_CTX_EXECUTION_DATE=2022-09-05T00:00:00+00:00
AIRFLOW_CTX_TRY_NUMBER=1
AIRFLOW_CTX_DAG_RUN_ID=scheduled__2022-09-05T00:00:00+00:00
[2023-02-10 17:28:22,731] {subprocess.py:62} INFO - Tmp dir root location: 
 /var/folders/b_/44w2czd50d77jsslrsmc4_sc0000gn/T
[2023-02-10 17:28:22,731] {subprocess.py:74} INFO - Running command: ['bash', '-c', 'mkdir -p  "/Users/francilenesilva/Documents/data-engineer/apache-airflow/orquestrando-pipeline1/data-pipeline/airflow-alura/semana=2022-09-12"']
[2023-02-10 17:28:22,735] {subprocess.py:85} INFO - Output:
[2023-02-10 17:28:22,738] {subprocess.py:96} INFO - Command exited with return code 0
[2023-02-10 17:28:22,745] {taskinstance.py:1395} INFO - Marking task as SUCCESS. dag_id=dados_climaticos, task_id=cria_pasta, execution_date=20220905T000000, start_date=20230210T172822, end_date=20230210T172822
[2023-02-10 17:28:22,757] {local_task_job.py:156} INFO - Task exited with return code 0
[2023-02-10 17:28:22,766] {local_task_job.py:273} INFO - 1 downstream tasks scheduled from follow-on schedule check
