[2023-02-10 14:19:08,368] {taskinstance.py:1159} INFO - Dependencies all met for <TaskInstance: dados_climaticos.cria_pasta scheduled__2022-08-29T00:00:00+00:00 [queued]>
[2023-02-10 14:19:08,370] {taskinstance.py:1159} INFO - Dependencies all met for <TaskInstance: dados_climaticos.cria_pasta scheduled__2022-08-29T00:00:00+00:00 [queued]>
[2023-02-10 14:19:08,370] {taskinstance.py:1356} INFO - 
--------------------------------------------------------------------------------
[2023-02-10 14:19:08,370] {taskinstance.py:1357} INFO - Starting attempt 1 of 1
[2023-02-10 14:19:08,370] {taskinstance.py:1358} INFO - 
--------------------------------------------------------------------------------
[2023-02-10 14:19:08,374] {taskinstance.py:1377} INFO - Executing <Task(BashOperator): cria_pasta> on 2022-08-29 00:00:00+00:00
[2023-02-10 14:19:08,376] {standard_task_runner.py:52} INFO - Started process 33071 to run task
[2023-02-10 14:19:08,379] {standard_task_runner.py:79} INFO - Running: ['airflow', 'tasks', 'run', 'dados_climaticos', 'cria_pasta', 'scheduled__2022-08-29T00:00:00+00:00', '--job-id', '49', '--raw', '--subdir', 'DAGS_FOLDER/dados_climaticos.py', '--cfg-path', '/var/folders/b_/44w2czd50d77jsslrsmc4_sc0000gn/T/tmp7t8icz6w', '--error-file', '/var/folders/b_/44w2czd50d77jsslrsmc4_sc0000gn/T/tmp87m9s941']
[2023-02-10 14:19:08,379] {standard_task_runner.py:80} INFO - Job 49: Subtask cria_pasta
[2023-02-10 14:19:08,400] {task_command.py:370} INFO - Running <TaskInstance: dados_climaticos.cria_pasta scheduled__2022-08-29T00:00:00+00:00 [running]> on host airdefrancilene.lan
[2023-02-10 14:19:08,409] {taskinstance.py:1889} ERROR - Task failed with exception
Traceback (most recent call last):
  File "/Users/francilenesilva/Documents/data-engineer/apache-airflow/orquestrando-pipeline1/data-pipeline/airflow-alura/venv/lib/python3.10/site-packages/airflow/models/taskinstance.py", line 1451, in _run_raw_task
    self._execute_task_with_callbacks(context, test_mode)
  File "/Users/francilenesilva/Documents/data-engineer/apache-airflow/orquestrando-pipeline1/data-pipeline/airflow-alura/venv/lib/python3.10/site-packages/airflow/models/taskinstance.py", line 1555, in _execute_task_with_callbacks
    task_orig = self.render_templates(context=context)
  File "/Users/francilenesilva/Documents/data-engineer/apache-airflow/orquestrando-pipeline1/data-pipeline/airflow-alura/venv/lib/python3.10/site-packages/airflow/models/taskinstance.py", line 2212, in render_templates
    rendered_task = self.task.render_template_fields(context)
  File "/Users/francilenesilva/Documents/data-engineer/apache-airflow/orquestrando-pipeline1/data-pipeline/airflow-alura/venv/lib/python3.10/site-packages/airflow/models/baseoperator.py", line 1185, in render_template_fields
    self._do_render_template_fields(self, self.template_fields, context, jinja_env, set())
  File "/Users/francilenesilva/Documents/data-engineer/apache-airflow/orquestrando-pipeline1/data-pipeline/airflow-alura/venv/lib/python3.10/site-packages/airflow/utils/session.py", line 71, in wrapper
    return func(*args, session=session, **kwargs)
  File "/Users/francilenesilva/Documents/data-engineer/apache-airflow/orquestrando-pipeline1/data-pipeline/airflow-alura/venv/lib/python3.10/site-packages/airflow/models/abstractoperator.py", line 344, in _do_render_template_fields
    rendered_content = self.render_template(
  File "/Users/francilenesilva/Documents/data-engineer/apache-airflow/orquestrando-pipeline1/data-pipeline/airflow-alura/venv/lib/python3.10/site-packages/airflow/models/abstractoperator.py", line 387, in render_template
    template = jinja_env.from_string(value)
  File "/Users/francilenesilva/Documents/data-engineer/apache-airflow/orquestrando-pipeline1/data-pipeline/airflow-alura/venv/lib/python3.10/site-packages/jinja2/environment.py", line 941, in from_string
    return cls.from_code(self, self.compile(source), globals, None)
  File "/Users/francilenesilva/Documents/data-engineer/apache-airflow/orquestrando-pipeline1/data-pipeline/airflow-alura/venv/lib/python3.10/site-packages/jinja2/environment.py", line 638, in compile
    self.handle_exception(source=source_hint)
  File "/Users/francilenesilva/Documents/data-engineer/apache-airflow/orquestrando-pipeline1/data-pipeline/airflow-alura/venv/lib/python3.10/site-packages/jinja2/environment.py", line 832, in handle_exception
    reraise(*rewrite_traceback_stack(source=source))
  File "/Users/francilenesilva/Documents/data-engineer/apache-airflow/orquestrando-pipeline1/data-pipeline/airflow-alura/venv/lib/python3.10/site-packages/jinja2/_compat.py", line 28, in reraise
    raise value.with_traceback(tb)
  File "<unknown>", line -1, in template
jinja2.exceptions.TemplateSyntaxError: unexpected end of template, expected ','.
[2023-02-10 14:19:08,411] {taskinstance.py:1395} INFO - Marking task as FAILED. dag_id=dados_climaticos, task_id=cria_pasta, execution_date=20220829T000000, start_date=20230210T141908, end_date=20230210T141908
[2023-02-10 14:19:08,413] {standard_task_runner.py:92} ERROR - Failed to execute job 49 for task cria_pasta (unexpected end of template, expected ','.; 33071)
[2023-02-10 14:19:08,441] {local_task_job.py:156} INFO - Task exited with return code 1
[2023-02-10 14:19:08,451] {local_task_job.py:273} INFO - 0 downstream tasks scheduled from follow-on schedule check
[2023-02-10 14:22:45,689] {taskinstance.py:1159} INFO - Dependencies all met for <TaskInstance: dados_climaticos.cria_pasta scheduled__2022-08-29T00:00:00+00:00 [queued]>
[2023-02-10 14:22:45,692] {taskinstance.py:1159} INFO - Dependencies all met for <TaskInstance: dados_climaticos.cria_pasta scheduled__2022-08-29T00:00:00+00:00 [queued]>
[2023-02-10 14:22:45,692] {taskinstance.py:1356} INFO - 
--------------------------------------------------------------------------------
[2023-02-10 14:22:45,692] {taskinstance.py:1357} INFO - Starting attempt 1 of 1
[2023-02-10 14:22:45,692] {taskinstance.py:1358} INFO - 
--------------------------------------------------------------------------------
[2023-02-10 14:22:45,695] {taskinstance.py:1377} INFO - Executing <Task(BashOperator): cria_pasta> on 2022-08-29 00:00:00+00:00
[2023-02-10 14:22:45,697] {standard_task_runner.py:52} INFO - Started process 33669 to run task
[2023-02-10 14:22:45,700] {standard_task_runner.py:79} INFO - Running: ['airflow', 'tasks', 'run', 'dados_climaticos', 'cria_pasta', 'scheduled__2022-08-29T00:00:00+00:00', '--job-id', '51', '--raw', '--subdir', 'DAGS_FOLDER/dados_climaticos.py', '--cfg-path', '/var/folders/b_/44w2czd50d77jsslrsmc4_sc0000gn/T/tmpwo80egr_', '--error-file', '/var/folders/b_/44w2czd50d77jsslrsmc4_sc0000gn/T/tmp_9s4nr1o']
[2023-02-10 14:22:45,700] {standard_task_runner.py:80} INFO - Job 51: Subtask cria_pasta
[2023-02-10 14:22:45,716] {task_command.py:370} INFO - Running <TaskInstance: dados_climaticos.cria_pasta scheduled__2022-08-29T00:00:00+00:00 [running]> on host airdefrancilene.lan
[2023-02-10 14:22:45,725] {taskinstance.py:1889} ERROR - Task failed with exception
Traceback (most recent call last):
  File "/Users/francilenesilva/Documents/data-engineer/apache-airflow/orquestrando-pipeline1/data-pipeline/airflow-alura/venv/lib/python3.10/site-packages/airflow/models/taskinstance.py", line 1451, in _run_raw_task
    self._execute_task_with_callbacks(context, test_mode)
  File "/Users/francilenesilva/Documents/data-engineer/apache-airflow/orquestrando-pipeline1/data-pipeline/airflow-alura/venv/lib/python3.10/site-packages/airflow/models/taskinstance.py", line 1555, in _execute_task_with_callbacks
    task_orig = self.render_templates(context=context)
  File "/Users/francilenesilva/Documents/data-engineer/apache-airflow/orquestrando-pipeline1/data-pipeline/airflow-alura/venv/lib/python3.10/site-packages/airflow/models/taskinstance.py", line 2212, in render_templates
    rendered_task = self.task.render_template_fields(context)
  File "/Users/francilenesilva/Documents/data-engineer/apache-airflow/orquestrando-pipeline1/data-pipeline/airflow-alura/venv/lib/python3.10/site-packages/airflow/models/baseoperator.py", line 1185, in render_template_fields
    self._do_render_template_fields(self, self.template_fields, context, jinja_env, set())
  File "/Users/francilenesilva/Documents/data-engineer/apache-airflow/orquestrando-pipeline1/data-pipeline/airflow-alura/venv/lib/python3.10/site-packages/airflow/utils/session.py", line 71, in wrapper
    return func(*args, session=session, **kwargs)
  File "/Users/francilenesilva/Documents/data-engineer/apache-airflow/orquestrando-pipeline1/data-pipeline/airflow-alura/venv/lib/python3.10/site-packages/airflow/models/abstractoperator.py", line 344, in _do_render_template_fields
    rendered_content = self.render_template(
  File "/Users/francilenesilva/Documents/data-engineer/apache-airflow/orquestrando-pipeline1/data-pipeline/airflow-alura/venv/lib/python3.10/site-packages/airflow/models/abstractoperator.py", line 387, in render_template
    template = jinja_env.from_string(value)
  File "/Users/francilenesilva/Documents/data-engineer/apache-airflow/orquestrando-pipeline1/data-pipeline/airflow-alura/venv/lib/python3.10/site-packages/jinja2/environment.py", line 941, in from_string
    return cls.from_code(self, self.compile(source), globals, None)
  File "/Users/francilenesilva/Documents/data-engineer/apache-airflow/orquestrando-pipeline1/data-pipeline/airflow-alura/venv/lib/python3.10/site-packages/jinja2/environment.py", line 638, in compile
    self.handle_exception(source=source_hint)
  File "/Users/francilenesilva/Documents/data-engineer/apache-airflow/orquestrando-pipeline1/data-pipeline/airflow-alura/venv/lib/python3.10/site-packages/jinja2/environment.py", line 832, in handle_exception
    reraise(*rewrite_traceback_stack(source=source))
  File "/Users/francilenesilva/Documents/data-engineer/apache-airflow/orquestrando-pipeline1/data-pipeline/airflow-alura/venv/lib/python3.10/site-packages/jinja2/_compat.py", line 28, in reraise
    raise value.with_traceback(tb)
  File "<unknown>", line -1, in template
jinja2.exceptions.TemplateSyntaxError: unexpected end of template, expected ','.
[2023-02-10 14:22:45,727] {taskinstance.py:1395} INFO - Marking task as FAILED. dag_id=dados_climaticos, task_id=cria_pasta, execution_date=20220829T000000, start_date=20230210T142245, end_date=20230210T142245
[2023-02-10 14:22:45,730] {standard_task_runner.py:92} ERROR - Failed to execute job 51 for task cria_pasta (unexpected end of template, expected ','.; 33669)
[2023-02-10 14:22:45,759] {local_task_job.py:156} INFO - Task exited with return code 1
[2023-02-10 14:22:45,770] {local_task_job.py:273} INFO - 0 downstream tasks scheduled from follow-on schedule check
[2023-02-10 17:28:20,170] {taskinstance.py:1159} INFO - Dependencies all met for <TaskInstance: dados_climaticos.cria_pasta scheduled__2022-08-29T00:00:00+00:00 [queued]>
[2023-02-10 17:28:20,172] {taskinstance.py:1159} INFO - Dependencies all met for <TaskInstance: dados_climaticos.cria_pasta scheduled__2022-08-29T00:00:00+00:00 [queued]>
[2023-02-10 17:28:20,172] {taskinstance.py:1356} INFO - 
--------------------------------------------------------------------------------
[2023-02-10 17:28:20,172] {taskinstance.py:1357} INFO - Starting attempt 1 of 1
[2023-02-10 17:28:20,172] {taskinstance.py:1358} INFO - 
--------------------------------------------------------------------------------
[2023-02-10 17:28:20,176] {taskinstance.py:1377} INFO - Executing <Task(BashOperator): cria_pasta> on 2022-08-29 00:00:00+00:00
[2023-02-10 17:28:20,178] {standard_task_runner.py:52} INFO - Started process 55135 to run task
[2023-02-10 17:28:20,180] {standard_task_runner.py:79} INFO - Running: ['airflow', 'tasks', 'run', 'dados_climaticos', 'cria_pasta', 'scheduled__2022-08-29T00:00:00+00:00', '--job-id', '67', '--raw', '--subdir', 'DAGS_FOLDER/dados_climaticos.py', '--cfg-path', '/var/folders/b_/44w2czd50d77jsslrsmc4_sc0000gn/T/tmp4ntp33k2', '--error-file', '/var/folders/b_/44w2czd50d77jsslrsmc4_sc0000gn/T/tmpgv30_ouq']
[2023-02-10 17:28:20,181] {standard_task_runner.py:80} INFO - Job 67: Subtask cria_pasta
[2023-02-10 17:28:20,197] {task_command.py:370} INFO - Running <TaskInstance: dados_climaticos.cria_pasta scheduled__2022-08-29T00:00:00+00:00 [running]> on host airdefrancilene.lan
[2023-02-10 17:28:20,213] {taskinstance.py:1569} INFO - Exporting the following env vars:
AIRFLOW_CTX_DAG_OWNER=airflow
AIRFLOW_CTX_DAG_ID=dados_climaticos
AIRFLOW_CTX_TASK_ID=cria_pasta
AIRFLOW_CTX_EXECUTION_DATE=2022-08-29T00:00:00+00:00
AIRFLOW_CTX_TRY_NUMBER=1
AIRFLOW_CTX_DAG_RUN_ID=scheduled__2022-08-29T00:00:00+00:00
[2023-02-10 17:28:20,214] {subprocess.py:62} INFO - Tmp dir root location: 
 /var/folders/b_/44w2czd50d77jsslrsmc4_sc0000gn/T
[2023-02-10 17:28:20,214] {subprocess.py:74} INFO - Running command: ['bash', '-c', 'mkdir -p  "/Users/francilenesilva/Documents/data-engineer/apache-airflow/orquestrando-pipeline1/data-pipeline/airflow-alura/semana=2022-09-05"']
[2023-02-10 17:28:20,218] {subprocess.py:85} INFO - Output:
[2023-02-10 17:28:20,221] {subprocess.py:96} INFO - Command exited with return code 0
[2023-02-10 17:28:20,229] {taskinstance.py:1395} INFO - Marking task as SUCCESS. dag_id=dados_climaticos, task_id=cria_pasta, execution_date=20220829T000000, start_date=20230210T172820, end_date=20230210T172820
[2023-02-10 17:28:20,238] {local_task_job.py:156} INFO - Task exited with return code 0
[2023-02-10 17:28:20,247] {local_task_job.py:273} INFO - 1 downstream tasks scheduled from follow-on schedule check
