[2023-02-10 14:28:53,535] {taskinstance.py:1159} INFO - Dependencies all met for <TaskInstance: dados_climaticos.extrai_dados scheduled__2023-01-30T00:00:00+00:00 [queued]>
[2023-02-10 14:28:53,537] {taskinstance.py:1159} INFO - Dependencies all met for <TaskInstance: dados_climaticos.extrai_dados scheduled__2023-01-30T00:00:00+00:00 [queued]>
[2023-02-10 14:28:53,537] {taskinstance.py:1356} INFO - 
--------------------------------------------------------------------------------
[2023-02-10 14:28:53,537] {taskinstance.py:1357} INFO - Starting attempt 1 of 1
[2023-02-10 14:28:53,537] {taskinstance.py:1358} INFO - 
--------------------------------------------------------------------------------
[2023-02-10 14:28:53,540] {taskinstance.py:1377} INFO - Executing <Task(PythonOperator): extrai_dados> on 2023-01-30 00:00:00+00:00
[2023-02-10 14:28:53,543] {standard_task_runner.py:52} INFO - Started process 34612 to run task
[2023-02-10 14:28:53,545] {standard_task_runner.py:79} INFO - Running: ['airflow', 'tasks', 'run', 'dados_climaticos', 'extrai_dados', 'scheduled__2023-01-30T00:00:00+00:00', '--job-id', '63', '--raw', '--subdir', 'DAGS_FOLDER/dados_climaticos.py', '--cfg-path', '/var/folders/b_/44w2czd50d77jsslrsmc4_sc0000gn/T/tmpmlej4pul', '--error-file', '/var/folders/b_/44w2czd50d77jsslrsmc4_sc0000gn/T/tmp_gx1_gz6']
[2023-02-10 14:28:53,546] {standard_task_runner.py:80} INFO - Job 63: Subtask extrai_dados
[2023-02-10 14:28:53,561] {task_command.py:370} INFO - Running <TaskInstance: dados_climaticos.extrai_dados scheduled__2023-01-30T00:00:00+00:00 [running]> on host airdefrancilene.lan
[2023-02-10 14:28:53,570] {taskinstance.py:1889} ERROR - Task failed with exception
Traceback (most recent call last):
  File "/Users/francilenesilva/Documents/data-engineer/apache-airflow/orquestrando-pipeline1/data-pipeline/airflow-alura/venv/lib/python3.10/site-packages/airflow/models/taskinstance.py", line 1451, in _run_raw_task
    self._execute_task_with_callbacks(context, test_mode)
  File "/Users/francilenesilva/Documents/data-engineer/apache-airflow/orquestrando-pipeline1/data-pipeline/airflow-alura/venv/lib/python3.10/site-packages/airflow/models/taskinstance.py", line 1555, in _execute_task_with_callbacks
    task_orig = self.render_templates(context=context)
  File "/Users/francilenesilva/Documents/data-engineer/apache-airflow/orquestrando-pipeline1/data-pipeline/airflow-alura/venv/lib/python3.10/site-packages/airflow/models/taskinstance.py", line 2212, in render_templates
    rendered_task = self.task.render_template_fields(context)
  File "/Users/francilenesilva/Documents/data-engineer/apache-airflow/orquestrando-pipeline1/data-pipeline/airflow-alura/venv/lib/python3.10/site-packages/airflow/models/baseoperator.py", line 1185, in render_template_fields
    self._do_render_template_fields(self, self.template_fields, context, jinja_env, set())
  File "/Users/francilenesilva/Documents/data-engineer/apache-airflow/orquestrando-pipeline1/data-pipeline/airflow-alura/venv/lib/python3.10/site-packages/airflow/utils/session.py", line 71, in wrapper
    return func(*args, session=session, **kwargs)
  File "/Users/francilenesilva/Documents/data-engineer/apache-airflow/orquestrando-pipeline1/data-pipeline/airflow-alura/venv/lib/python3.10/site-packages/airflow/models/abstractoperator.py", line 344, in _do_render_template_fields
    rendered_content = self.render_template(
  File "/Users/francilenesilva/Documents/data-engineer/apache-airflow/orquestrando-pipeline1/data-pipeline/airflow-alura/venv/lib/python3.10/site-packages/airflow/models/abstractoperator.py", line 404, in render_template
    return {key: self.render_template(value, context, jinja_env) for key, value in value.items()}
  File "/Users/francilenesilva/Documents/data-engineer/apache-airflow/orquestrando-pipeline1/data-pipeline/airflow-alura/venv/lib/python3.10/site-packages/airflow/models/abstractoperator.py", line 404, in <dictcomp>
    return {key: self.render_template(value, context, jinja_env) for key, value in value.items()}
  File "/Users/francilenesilva/Documents/data-engineer/apache-airflow/orquestrando-pipeline1/data-pipeline/airflow-alura/venv/lib/python3.10/site-packages/airflow/models/abstractoperator.py", line 387, in render_template
    template = jinja_env.from_string(value)
  File "/Users/francilenesilva/Documents/data-engineer/apache-airflow/orquestrando-pipeline1/data-pipeline/airflow-alura/venv/lib/python3.10/site-packages/jinja2/environment.py", line 941, in from_string
    return cls.from_code(self, self.compile(source), globals, None)
  File "/Users/francilenesilva/Documents/data-engineer/apache-airflow/orquestrando-pipeline1/data-pipeline/airflow-alura/venv/lib/python3.10/site-packages/jinja2/environment.py", line 638, in compile
    self.handle_exception(source=source_hint)
  File "/Users/francilenesilva/Documents/data-engineer/apache-airflow/orquestrando-pipeline1/data-pipeline/airflow-alura/venv/lib/python3.10/site-packages/jinja2/environment.py", line 832, in handle_exception
    reraise(*rewrite_traceback_stack(source=source))
  File "/Users/francilenesilva/Documents/data-engineer/apache-airflow/orquestrando-pipeline1/data-pipeline/airflow-alura/venv/lib/python3.10/site-packages/jinja2/_compat.py", line 28, in reraise
    raise value.with_traceback(tb)
  File "<unknown>", line -1, in template
jinja2.exceptions.TemplateSyntaxError: unexpected char '"' at 29
[2023-02-10 14:28:53,573] {taskinstance.py:1395} INFO - Marking task as FAILED. dag_id=dados_climaticos, task_id=extrai_dados, execution_date=20230130T000000, start_date=20230210T142853, end_date=20230210T142853
[2023-02-10 14:28:53,575] {standard_task_runner.py:92} ERROR - Failed to execute job 63 for task extrai_dados (unexpected char '"' at 29; 34612)
[2023-02-10 14:28:53,606] {local_task_job.py:156} INFO - Task exited with return code 1
[2023-02-10 14:28:53,613] {local_task_job.py:273} INFO - 0 downstream tasks scheduled from follow-on schedule check
[2023-02-10 14:54:44,861] {taskinstance.py:1159} INFO - Dependencies all met for <TaskInstance: dados_climaticos.extrai_dados scheduled__2023-01-30T00:00:00+00:00 [queued]>
[2023-02-10 14:54:44,863] {taskinstance.py:1159} INFO - Dependencies all met for <TaskInstance: dados_climaticos.extrai_dados scheduled__2023-01-30T00:00:00+00:00 [queued]>
[2023-02-10 14:54:44,863] {taskinstance.py:1356} INFO - 
--------------------------------------------------------------------------------
[2023-02-10 14:54:44,863] {taskinstance.py:1357} INFO - Starting attempt 1 of 1
[2023-02-10 14:54:44,863] {taskinstance.py:1358} INFO - 
--------------------------------------------------------------------------------
[2023-02-10 14:54:44,866] {taskinstance.py:1377} INFO - Executing <Task(PythonOperator): extrai_dados> on 2023-01-30 00:00:00+00:00
[2023-02-10 14:54:44,868] {standard_task_runner.py:52} INFO - Started process 38286 to run task
[2023-02-10 14:54:44,871] {standard_task_runner.py:79} INFO - Running: ['airflow', 'tasks', 'run', 'dados_climaticos', 'extrai_dados', 'scheduled__2023-01-30T00:00:00+00:00', '--job-id', '73', '--raw', '--subdir', 'DAGS_FOLDER/dados_climaticos.py', '--cfg-path', '/var/folders/b_/44w2czd50d77jsslrsmc4_sc0000gn/T/tmpmvm5s95y', '--error-file', '/var/folders/b_/44w2czd50d77jsslrsmc4_sc0000gn/T/tmp7c9lcoir']
[2023-02-10 14:54:44,872] {standard_task_runner.py:80} INFO - Job 73: Subtask extrai_dados
[2023-02-10 14:54:44,887] {task_command.py:370} INFO - Running <TaskInstance: dados_climaticos.extrai_dados scheduled__2023-01-30T00:00:00+00:00 [running]> on host airdefrancilene.lan
[2023-02-10 14:54:44,896] {taskinstance.py:1889} ERROR - Task failed with exception
Traceback (most recent call last):
  File "/Users/francilenesilva/Documents/data-engineer/apache-airflow/orquestrando-pipeline1/data-pipeline/airflow-alura/venv/lib/python3.10/site-packages/airflow/models/taskinstance.py", line 1451, in _run_raw_task
    self._execute_task_with_callbacks(context, test_mode)
  File "/Users/francilenesilva/Documents/data-engineer/apache-airflow/orquestrando-pipeline1/data-pipeline/airflow-alura/venv/lib/python3.10/site-packages/airflow/models/taskinstance.py", line 1555, in _execute_task_with_callbacks
    task_orig = self.render_templates(context=context)
  File "/Users/francilenesilva/Documents/data-engineer/apache-airflow/orquestrando-pipeline1/data-pipeline/airflow-alura/venv/lib/python3.10/site-packages/airflow/models/taskinstance.py", line 2212, in render_templates
    rendered_task = self.task.render_template_fields(context)
  File "/Users/francilenesilva/Documents/data-engineer/apache-airflow/orquestrando-pipeline1/data-pipeline/airflow-alura/venv/lib/python3.10/site-packages/airflow/models/baseoperator.py", line 1185, in render_template_fields
    self._do_render_template_fields(self, self.template_fields, context, jinja_env, set())
  File "/Users/francilenesilva/Documents/data-engineer/apache-airflow/orquestrando-pipeline1/data-pipeline/airflow-alura/venv/lib/python3.10/site-packages/airflow/utils/session.py", line 71, in wrapper
    return func(*args, session=session, **kwargs)
  File "/Users/francilenesilva/Documents/data-engineer/apache-airflow/orquestrando-pipeline1/data-pipeline/airflow-alura/venv/lib/python3.10/site-packages/airflow/models/abstractoperator.py", line 344, in _do_render_template_fields
    rendered_content = self.render_template(
  File "/Users/francilenesilva/Documents/data-engineer/apache-airflow/orquestrando-pipeline1/data-pipeline/airflow-alura/venv/lib/python3.10/site-packages/airflow/models/abstractoperator.py", line 404, in render_template
    return {key: self.render_template(value, context, jinja_env) for key, value in value.items()}
  File "/Users/francilenesilva/Documents/data-engineer/apache-airflow/orquestrando-pipeline1/data-pipeline/airflow-alura/venv/lib/python3.10/site-packages/airflow/models/abstractoperator.py", line 404, in <dictcomp>
    return {key: self.render_template(value, context, jinja_env) for key, value in value.items()}
  File "/Users/francilenesilva/Documents/data-engineer/apache-airflow/orquestrando-pipeline1/data-pipeline/airflow-alura/venv/lib/python3.10/site-packages/airflow/models/abstractoperator.py", line 387, in render_template
    template = jinja_env.from_string(value)
  File "/Users/francilenesilva/Documents/data-engineer/apache-airflow/orquestrando-pipeline1/data-pipeline/airflow-alura/venv/lib/python3.10/site-packages/jinja2/environment.py", line 941, in from_string
    return cls.from_code(self, self.compile(source), globals, None)
  File "/Users/francilenesilva/Documents/data-engineer/apache-airflow/orquestrando-pipeline1/data-pipeline/airflow-alura/venv/lib/python3.10/site-packages/jinja2/environment.py", line 638, in compile
    self.handle_exception(source=source_hint)
  File "/Users/francilenesilva/Documents/data-engineer/apache-airflow/orquestrando-pipeline1/data-pipeline/airflow-alura/venv/lib/python3.10/site-packages/jinja2/environment.py", line 832, in handle_exception
    reraise(*rewrite_traceback_stack(source=source))
  File "/Users/francilenesilva/Documents/data-engineer/apache-airflow/orquestrando-pipeline1/data-pipeline/airflow-alura/venv/lib/python3.10/site-packages/jinja2/_compat.py", line 28, in reraise
    raise value.with_traceback(tb)
  File "<unknown>", line -1, in template
jinja2.exceptions.TemplateSyntaxError: unexpected char '"' at 29
[2023-02-10 14:54:44,899] {taskinstance.py:1395} INFO - Marking task as FAILED. dag_id=dados_climaticos, task_id=extrai_dados, execution_date=20230130T000000, start_date=20230210T145444, end_date=20230210T145444
[2023-02-10 14:54:44,902] {standard_task_runner.py:92} ERROR - Failed to execute job 73 for task extrai_dados (unexpected char '"' at 29; 38286)
[2023-02-10 14:54:44,931] {local_task_job.py:156} INFO - Task exited with return code 1
[2023-02-10 14:54:44,939] {local_task_job.py:273} INFO - 0 downstream tasks scheduled from follow-on schedule check
[2023-02-10 14:59:00,073] {taskinstance.py:1159} INFO - Dependencies all met for <TaskInstance: dados_climaticos.extrai_dados scheduled__2023-01-30T00:00:00+00:00 [queued]>
[2023-02-10 14:59:00,076] {taskinstance.py:1159} INFO - Dependencies all met for <TaskInstance: dados_climaticos.extrai_dados scheduled__2023-01-30T00:00:00+00:00 [queued]>
[2023-02-10 14:59:00,076] {taskinstance.py:1356} INFO - 
--------------------------------------------------------------------------------
[2023-02-10 14:59:00,076] {taskinstance.py:1357} INFO - Starting attempt 1 of 1
[2023-02-10 14:59:00,076] {taskinstance.py:1358} INFO - 
--------------------------------------------------------------------------------
[2023-02-10 14:59:00,079] {taskinstance.py:1377} INFO - Executing <Task(PythonOperator): extrai_dados> on 2023-01-30 00:00:00+00:00
[2023-02-10 14:59:00,081] {standard_task_runner.py:52} INFO - Started process 38918 to run task
[2023-02-10 14:59:00,084] {standard_task_runner.py:79} INFO - Running: ['airflow', 'tasks', 'run', 'dados_climaticos', 'extrai_dados', 'scheduled__2023-01-30T00:00:00+00:00', '--job-id', '75', '--raw', '--subdir', 'DAGS_FOLDER/dados_climaticos.py', '--cfg-path', '/var/folders/b_/44w2czd50d77jsslrsmc4_sc0000gn/T/tmppjisube5', '--error-file', '/var/folders/b_/44w2czd50d77jsslrsmc4_sc0000gn/T/tmpd3i5zch3']
[2023-02-10 14:59:00,085] {standard_task_runner.py:80} INFO - Job 75: Subtask extrai_dados
[2023-02-10 14:59:00,108] {task_command.py:370} INFO - Running <TaskInstance: dados_climaticos.extrai_dados scheduled__2023-01-30T00:00:00+00:00 [running]> on host airdefrancilene.lan
[2023-02-10 14:59:00,129] {taskinstance.py:1569} INFO - Exporting the following env vars:
AIRFLOW_CTX_DAG_OWNER=airflow
AIRFLOW_CTX_DAG_ID=dados_climaticos
AIRFLOW_CTX_TASK_ID=extrai_dados
AIRFLOW_CTX_EXECUTION_DATE=2023-01-30T00:00:00+00:00
AIRFLOW_CTX_TRY_NUMBER=1
AIRFLOW_CTX_DAG_RUN_ID=scheduled__2023-01-30T00:00:00+00:00
[2023-02-10 14:59:00,130] {taskinstance.py:1889} ERROR - Task failed with exception
Traceback (most recent call last):
  File "/Users/francilenesilva/Documents/data-engineer/apache-airflow/orquestrando-pipeline1/data-pipeline/airflow-alura/venv/lib/python3.10/site-packages/airflow/operators/python.py", line 171, in execute
    return_value = self.execute_callable()
  File "/Users/francilenesilva/Documents/data-engineer/apache-airflow/orquestrando-pipeline1/data-pipeline/airflow-alura/venv/lib/python3.10/site-packages/airflow/operators/python.py", line 189, in execute_callable
    return self.python_callable(*self.op_args, **self.op_kwargs)
  File "/Users/francilenesilva/Documents/data-engineer/apache-airflow/orquestrando-pipeline1/data-pipeline/airflow-alura/dags/dados_climaticos.py", line 33, in extrai_dados
    f'{city}/{data_interval_end}/{ds_add(data_interval_end, 7)}?unitGroup=metric&include=days&key={key}&contentType=csv')
  File "/Users/francilenesilva/Documents/data-engineer/apache-airflow/orquestrando-pipeline1/data-pipeline/airflow-alura/venv/lib/python3.10/site-packages/airflow/macros/__init__.py", line 44, in ds_add
    dt = datetime.strptime(str(ds), "%Y-%m-%d") + timedelta(days=days)
  File "/opt/homebrew/Cellar/python@3.10/3.10.9/Frameworks/Python.framework/Versions/3.10/lib/python3.10/_strptime.py", line 568, in _strptime_datetime
    tt, fraction, gmtoff_fraction = _strptime(data_string, format)
  File "/opt/homebrew/Cellar/python@3.10/3.10.9/Frameworks/Python.framework/Versions/3.10/lib/python3.10/_strptime.py", line 352, in _strptime
    raise ValueError("unconverted data remains: %s" %
ValueError: unconverted data remains: T00:00:00+00:00
[2023-02-10 14:59:00,132] {taskinstance.py:1395} INFO - Marking task as FAILED. dag_id=dados_climaticos, task_id=extrai_dados, execution_date=20230130T000000, start_date=20230210T145900, end_date=20230210T145900
[2023-02-10 14:59:00,134] {standard_task_runner.py:92} ERROR - Failed to execute job 75 for task extrai_dados (unconverted data remains: T00:00:00+00:00; 38918)
[2023-02-10 14:59:00,143] {local_task_job.py:156} INFO - Task exited with return code 1
[2023-02-10 14:59:00,150] {local_task_job.py:273} INFO - 0 downstream tasks scheduled from follow-on schedule check
[2023-02-10 17:29:32,505] {taskinstance.py:1159} INFO - Dependencies all met for <TaskInstance: dados_climaticos.extrai_dados scheduled__2023-01-30T00:00:00+00:00 [queued]>
[2023-02-10 17:29:32,507] {taskinstance.py:1159} INFO - Dependencies all met for <TaskInstance: dados_climaticos.extrai_dados scheduled__2023-01-30T00:00:00+00:00 [queued]>
[2023-02-10 17:29:32,507] {taskinstance.py:1356} INFO - 
--------------------------------------------------------------------------------
[2023-02-10 17:29:32,507] {taskinstance.py:1357} INFO - Starting attempt 1 of 1
[2023-02-10 17:29:32,507] {taskinstance.py:1358} INFO - 
--------------------------------------------------------------------------------
[2023-02-10 17:29:32,511] {taskinstance.py:1377} INFO - Executing <Task(PythonOperator): extrai_dados> on 2023-01-30 00:00:00+00:00
[2023-02-10 17:29:32,513] {standard_task_runner.py:52} INFO - Started process 55387 to run task
[2023-02-10 17:29:32,515] {standard_task_runner.py:79} INFO - Running: ['airflow', 'tasks', 'run', 'dados_climaticos', 'extrai_dados', 'scheduled__2023-01-30T00:00:00+00:00', '--job-id', '113', '--raw', '--subdir', 'DAGS_FOLDER/dados_climaticos.py', '--cfg-path', '/var/folders/b_/44w2czd50d77jsslrsmc4_sc0000gn/T/tmpcoebt33l', '--error-file', '/var/folders/b_/44w2czd50d77jsslrsmc4_sc0000gn/T/tmp9_tvlb22']
[2023-02-10 17:29:32,516] {standard_task_runner.py:80} INFO - Job 113: Subtask extrai_dados
[2023-02-10 17:29:32,532] {task_command.py:370} INFO - Running <TaskInstance: dados_climaticos.extrai_dados scheduled__2023-01-30T00:00:00+00:00 [running]> on host airdefrancilene.lan
[2023-02-10 17:29:32,549] {taskinstance.py:1569} INFO - Exporting the following env vars:
AIRFLOW_CTX_DAG_OWNER=airflow
AIRFLOW_CTX_DAG_ID=dados_climaticos
AIRFLOW_CTX_TASK_ID=extrai_dados
AIRFLOW_CTX_EXECUTION_DATE=2023-01-30T00:00:00+00:00
AIRFLOW_CTX_TRY_NUMBER=1
AIRFLOW_CTX_DAG_RUN_ID=scheduled__2023-01-30T00:00:00+00:00
[2023-02-10 17:29:32,664] {local_task_job.py:156} INFO - Task exited with return code Negsignal.SIGSEGV
[2023-02-10 17:29:32,670] {taskinstance.py:1395} INFO - Marking task as FAILED. dag_id=dados_climaticos, task_id=extrai_dados, execution_date=20230130T000000, start_date=20230210T172932, end_date=20230210T172932
[2023-02-10 17:29:32,676] {local_task_job.py:273} INFO - 0 downstream tasks scheduled from follow-on schedule check
[2023-02-10 17:33:34,868] {taskinstance.py:1159} INFO - Dependencies all met for <TaskInstance: dados_climaticos.extrai_dados scheduled__2023-01-30T00:00:00+00:00 [queued]>
[2023-02-10 17:33:34,870] {taskinstance.py:1159} INFO - Dependencies all met for <TaskInstance: dados_climaticos.extrai_dados scheduled__2023-01-30T00:00:00+00:00 [queued]>
[2023-02-10 17:33:34,870] {taskinstance.py:1356} INFO - 
--------------------------------------------------------------------------------
[2023-02-10 17:33:34,870] {taskinstance.py:1357} INFO - Starting attempt 1 of 1
[2023-02-10 17:33:34,870] {taskinstance.py:1358} INFO - 
--------------------------------------------------------------------------------
[2023-02-10 17:33:34,874] {taskinstance.py:1377} INFO - Executing <Task(PythonOperator): extrai_dados> on 2023-01-30 00:00:00+00:00
[2023-02-10 17:33:34,876] {standard_task_runner.py:52} INFO - Started process 55963 to run task
[2023-02-10 17:33:34,879] {standard_task_runner.py:79} INFO - Running: ['airflow', 'tasks', 'run', 'dados_climaticos', 'extrai_dados', 'scheduled__2023-01-30T00:00:00+00:00', '--job-id', '129', '--raw', '--subdir', 'DAGS_FOLDER/dados_climaticos.py', '--cfg-path', '/var/folders/b_/44w2czd50d77jsslrsmc4_sc0000gn/T/tmpfxv8u876', '--error-file', '/var/folders/b_/44w2czd50d77jsslrsmc4_sc0000gn/T/tmpuuo2dgfb']
[2023-02-10 17:33:34,879] {standard_task_runner.py:80} INFO - Job 129: Subtask extrai_dados
[2023-02-10 17:33:34,900] {task_command.py:370} INFO - Running <TaskInstance: dados_climaticos.extrai_dados scheduled__2023-01-30T00:00:00+00:00 [running]> on host airdefrancilene.lan
[2023-02-10 17:33:34,923] {taskinstance.py:1569} INFO - Exporting the following env vars:
AIRFLOW_CTX_DAG_OWNER=airflow
AIRFLOW_CTX_DAG_ID=dados_climaticos
AIRFLOW_CTX_TASK_ID=extrai_dados
AIRFLOW_CTX_EXECUTION_DATE=2023-01-30T00:00:00+00:00
AIRFLOW_CTX_TRY_NUMBER=1
AIRFLOW_CTX_DAG_RUN_ID=scheduled__2023-01-30T00:00:00+00:00
[2023-02-10 17:33:35,025] {local_task_job.py:156} INFO - Task exited with return code Negsignal.SIGSEGV
[2023-02-10 17:33:35,030] {taskinstance.py:1395} INFO - Marking task as FAILED. dag_id=dados_climaticos, task_id=extrai_dados, execution_date=20230130T000000, start_date=20230210T173334, end_date=20230210T173335
[2023-02-10 17:33:35,036] {local_task_job.py:273} INFO - 0 downstream tasks scheduled from follow-on schedule check
[2023-02-10 17:35:55,994] {taskinstance.py:1159} INFO - Dependencies all met for <TaskInstance: dados_climaticos.extrai_dados scheduled__2023-01-30T00:00:00+00:00 [queued]>
[2023-02-10 17:35:55,996] {taskinstance.py:1159} INFO - Dependencies all met for <TaskInstance: dados_climaticos.extrai_dados scheduled__2023-01-30T00:00:00+00:00 [queued]>
[2023-02-10 17:35:55,996] {taskinstance.py:1356} INFO - 
--------------------------------------------------------------------------------
[2023-02-10 17:35:55,996] {taskinstance.py:1357} INFO - Starting attempt 1 of 1
[2023-02-10 17:35:55,996] {taskinstance.py:1358} INFO - 
--------------------------------------------------------------------------------
[2023-02-10 17:35:56,000] {taskinstance.py:1377} INFO - Executing <Task(PythonOperator): extrai_dados> on 2023-01-30 00:00:00+00:00
[2023-02-10 17:35:56,002] {standard_task_runner.py:52} INFO - Started process 56288 to run task
[2023-02-10 17:35:56,005] {standard_task_runner.py:79} INFO - Running: ['airflow', 'tasks', 'run', 'dados_climaticos', 'extrai_dados', 'scheduled__2023-01-30T00:00:00+00:00', '--job-id', '123', '--raw', '--subdir', 'DAGS_FOLDER/dados_climaticos.py', '--cfg-path', '/var/folders/b_/44w2czd50d77jsslrsmc4_sc0000gn/T/tmp7op0lzf4', '--error-file', '/var/folders/b_/44w2czd50d77jsslrsmc4_sc0000gn/T/tmpyfvdnb03']
[2023-02-10 17:35:56,005] {standard_task_runner.py:80} INFO - Job 123: Subtask extrai_dados
[2023-02-10 17:35:56,022] {task_command.py:370} INFO - Running <TaskInstance: dados_climaticos.extrai_dados scheduled__2023-01-30T00:00:00+00:00 [running]> on host airdefrancilene.lan
[2023-02-10 17:35:56,042] {taskinstance.py:1569} INFO - Exporting the following env vars:
AIRFLOW_CTX_DAG_OWNER=airflow
AIRFLOW_CTX_DAG_ID=dados_climaticos
AIRFLOW_CTX_TASK_ID=extrai_dados
AIRFLOW_CTX_EXECUTION_DATE=2023-01-30T00:00:00+00:00
AIRFLOW_CTX_TRY_NUMBER=1
AIRFLOW_CTX_DAG_RUN_ID=scheduled__2023-01-30T00:00:00+00:00
[2023-02-10 17:35:56,153] {local_task_job.py:156} INFO - Task exited with return code Negsignal.SIGSEGV
[2023-02-10 17:35:56,159] {taskinstance.py:1395} INFO - Marking task as FAILED. dag_id=dados_climaticos, task_id=extrai_dados, execution_date=20230130T000000, start_date=20230210T173555, end_date=20230210T173556
[2023-02-10 17:35:56,165] {local_task_job.py:273} INFO - 0 downstream tasks scheduled from follow-on schedule check
[2023-02-10 17:46:53,094] {taskinstance.py:1159} INFO - Dependencies all met for <TaskInstance: dados_climaticos.extrai_dados scheduled__2023-01-30T00:00:00+00:00 [queued]>
[2023-02-10 17:46:53,096] {taskinstance.py:1159} INFO - Dependencies all met for <TaskInstance: dados_climaticos.extrai_dados scheduled__2023-01-30T00:00:00+00:00 [queued]>
[2023-02-10 17:46:53,096] {taskinstance.py:1356} INFO - 
--------------------------------------------------------------------------------
[2023-02-10 17:46:53,096] {taskinstance.py:1357} INFO - Starting attempt 1 of 1
[2023-02-10 17:46:53,096] {taskinstance.py:1358} INFO - 
--------------------------------------------------------------------------------
[2023-02-10 17:46:53,100] {taskinstance.py:1377} INFO - Executing <Task(PythonOperator): extrai_dados> on 2023-01-30 00:00:00+00:00
[2023-02-10 17:46:53,102] {standard_task_runner.py:52} INFO - Started process 57696 to run task
[2023-02-10 17:46:53,104] {standard_task_runner.py:79} INFO - Running: ['airflow', 'tasks', 'run', 'dados_climaticos', 'extrai_dados', 'scheduled__2023-01-30T00:00:00+00:00', '--job-id', '125', '--raw', '--subdir', 'DAGS_FOLDER/dados_climaticos.py', '--cfg-path', '/var/folders/b_/44w2czd50d77jsslrsmc4_sc0000gn/T/tmp5ujqr5gn', '--error-file', '/var/folders/b_/44w2czd50d77jsslrsmc4_sc0000gn/T/tmp4inlwkfb']
[2023-02-10 17:46:53,105] {standard_task_runner.py:80} INFO - Job 125: Subtask extrai_dados
[2023-02-10 17:46:53,120] {task_command.py:370} INFO - Running <TaskInstance: dados_climaticos.extrai_dados scheduled__2023-01-30T00:00:00+00:00 [running]> on host airdefrancilene.lan
[2023-02-10 17:46:53,138] {taskinstance.py:1569} INFO - Exporting the following env vars:
AIRFLOW_CTX_DAG_OWNER=airflow
AIRFLOW_CTX_DAG_ID=dados_climaticos
AIRFLOW_CTX_TASK_ID=extrai_dados
AIRFLOW_CTX_EXECUTION_DATE=2023-01-30T00:00:00+00:00
AIRFLOW_CTX_TRY_NUMBER=1
AIRFLOW_CTX_DAG_RUN_ID=scheduled__2023-01-30T00:00:00+00:00
[2023-02-10 17:46:53,256] {local_task_job.py:156} INFO - Task exited with return code Negsignal.SIGSEGV
[2023-02-10 17:46:53,262] {taskinstance.py:1395} INFO - Marking task as FAILED. dag_id=dados_climaticos, task_id=extrai_dados, execution_date=20230130T000000, start_date=20230210T174653, end_date=20230210T174653
[2023-02-10 17:46:53,268] {local_task_job.py:273} INFO - 0 downstream tasks scheduled from follow-on schedule check
[2023-02-10 17:56:14,542] {taskinstance.py:1159} INFO - Dependencies all met for <TaskInstance: dados_climaticos.extrai_dados scheduled__2023-01-30T00:00:00+00:00 [queued]>
[2023-02-10 17:56:14,545] {taskinstance.py:1159} INFO - Dependencies all met for <TaskInstance: dados_climaticos.extrai_dados scheduled__2023-01-30T00:00:00+00:00 [queued]>
[2023-02-10 17:56:14,545] {taskinstance.py:1356} INFO - 
--------------------------------------------------------------------------------
[2023-02-10 17:56:14,545] {taskinstance.py:1357} INFO - Starting attempt 1 of 1
[2023-02-10 17:56:14,545] {taskinstance.py:1358} INFO - 
--------------------------------------------------------------------------------
[2023-02-10 17:56:14,549] {taskinstance.py:1377} INFO - Executing <Task(PythonOperator): extrai_dados> on 2023-01-30 00:00:00+00:00
[2023-02-10 17:56:14,551] {standard_task_runner.py:52} INFO - Started process 59058 to run task
[2023-02-10 17:56:14,553] {standard_task_runner.py:79} INFO - Running: ['airflow', 'tasks', 'run', 'dados_climaticos', 'extrai_dados', 'scheduled__2023-01-30T00:00:00+00:00', '--job-id', '127', '--raw', '--subdir', 'DAGS_FOLDER/dados_climaticos.py', '--cfg-path', '/var/folders/b_/44w2czd50d77jsslrsmc4_sc0000gn/T/tmp_str9m3t', '--error-file', '/var/folders/b_/44w2czd50d77jsslrsmc4_sc0000gn/T/tmppgi0dz1_']
[2023-02-10 17:56:14,554] {standard_task_runner.py:80} INFO - Job 127: Subtask extrai_dados
[2023-02-10 17:56:14,571] {task_command.py:370} INFO - Running <TaskInstance: dados_climaticos.extrai_dados scheduled__2023-01-30T00:00:00+00:00 [running]> on host airdefrancilene.lan
[2023-02-10 17:56:14,588] {taskinstance.py:1569} INFO - Exporting the following env vars:
AIRFLOW_CTX_DAG_OWNER=airflow
AIRFLOW_CTX_DAG_ID=dados_climaticos
AIRFLOW_CTX_TASK_ID=extrai_dados
AIRFLOW_CTX_EXECUTION_DATE=2023-01-30T00:00:00+00:00
AIRFLOW_CTX_TRY_NUMBER=1
AIRFLOW_CTX_DAG_RUN_ID=scheduled__2023-01-30T00:00:00+00:00
[2023-02-10 17:56:14,595] {taskinstance.py:1889} ERROR - Task failed with exception
Traceback (most recent call last):
  File "/Users/francilenesilva/Documents/data-engineer/apache-airflow/orquestrando-pipeline1/data-pipeline/airflow-alura/venv/lib/python3.10/site-packages/airflow/operators/python.py", line 171, in execute
    return_value = self.execute_callable()
  File "/Users/francilenesilva/Documents/data-engineer/apache-airflow/orquestrando-pipeline1/data-pipeline/airflow-alura/venv/lib/python3.10/site-packages/airflow/operators/python.py", line 189, in execute_callable
    return self.python_callable(*self.op_args, **self.op_kwargs)
  File "/Users/francilenesilva/Documents/data-engineer/apache-airflow/orquestrando-pipeline1/data-pipeline/airflow-alura/dags/dados_climaticos.py", line 31, in extrai_dados
    dados = pd.read_csv(URL)
  File "/Users/francilenesilva/Documents/data-engineer/apache-airflow/orquestrando-pipeline1/data-pipeline/airflow-alura/venv/lib/python3.10/site-packages/pandas/util/_decorators.py", line 211, in wrapper
    return func(*args, **kwargs)
  File "/Users/francilenesilva/Documents/data-engineer/apache-airflow/orquestrando-pipeline1/data-pipeline/airflow-alura/venv/lib/python3.10/site-packages/pandas/util/_decorators.py", line 331, in wrapper
    return func(*args, **kwargs)
  File "/Users/francilenesilva/Documents/data-engineer/apache-airflow/orquestrando-pipeline1/data-pipeline/airflow-alura/venv/lib/python3.10/site-packages/pandas/io/parsers/readers.py", line 950, in read_csv
    return _read(filepath_or_buffer, kwds)
  File "/Users/francilenesilva/Documents/data-engineer/apache-airflow/orquestrando-pipeline1/data-pipeline/airflow-alura/venv/lib/python3.10/site-packages/pandas/io/parsers/readers.py", line 605, in _read
    parser = TextFileReader(filepath_or_buffer, **kwds)
  File "/Users/francilenesilva/Documents/data-engineer/apache-airflow/orquestrando-pipeline1/data-pipeline/airflow-alura/venv/lib/python3.10/site-packages/pandas/io/parsers/readers.py", line 1442, in __init__
    self._engine = self._make_engine(f, self.engine)
  File "/Users/francilenesilva/Documents/data-engineer/apache-airflow/orquestrando-pipeline1/data-pipeline/airflow-alura/venv/lib/python3.10/site-packages/pandas/io/parsers/readers.py", line 1735, in _make_engine
    self.handles = get_handle(
  File "/Users/francilenesilva/Documents/data-engineer/apache-airflow/orquestrando-pipeline1/data-pipeline/airflow-alura/venv/lib/python3.10/site-packages/pandas/io/common.py", line 713, in get_handle
    ioargs = _get_filepath_or_buffer(
  File "/Users/francilenesilva/Documents/data-engineer/apache-airflow/orquestrando-pipeline1/data-pipeline/airflow-alura/venv/lib/python3.10/site-packages/pandas/io/common.py", line 363, in _get_filepath_or_buffer
    with urlopen(req_info) as req:
  File "/Users/francilenesilva/Documents/data-engineer/apache-airflow/orquestrando-pipeline1/data-pipeline/airflow-alura/venv/lib/python3.10/site-packages/pandas/io/common.py", line 265, in urlopen
    return urllib.request.urlopen(*args, **kwargs)
  File "/opt/homebrew/Cellar/python@3.10/3.10.9/Frameworks/Python.framework/Versions/3.10/lib/python3.10/urllib/request.py", line 216, in urlopen
    return opener.open(url, data, timeout)
  File "/opt/homebrew/Cellar/python@3.10/3.10.9/Frameworks/Python.framework/Versions/3.10/lib/python3.10/urllib/request.py", line 519, in open
    response = self._open(req, data)
  File "/opt/homebrew/Cellar/python@3.10/3.10.9/Frameworks/Python.framework/Versions/3.10/lib/python3.10/urllib/request.py", line 536, in _open
    result = self._call_chain(self.handle_open, protocol, protocol +
  File "/opt/homebrew/Cellar/python@3.10/3.10.9/Frameworks/Python.framework/Versions/3.10/lib/python3.10/urllib/request.py", line 496, in _call_chain
    result = func(*args)
  File "/opt/homebrew/Cellar/python@3.10/3.10.9/Frameworks/Python.framework/Versions/3.10/lib/python3.10/urllib/request.py", line 1391, in https_open
    return self.do_open(http.client.HTTPSConnection, req,
  File "/opt/homebrew/Cellar/python@3.10/3.10.9/Frameworks/Python.framework/Versions/3.10/lib/python3.10/urllib/request.py", line 1348, in do_open
    h.request(req.get_method(), req.selector, req.data, headers,
  File "/opt/homebrew/Cellar/python@3.10/3.10.9/Frameworks/Python.framework/Versions/3.10/lib/python3.10/http/client.py", line 1282, in request
    self._send_request(method, url, body, headers, encode_chunked)
  File "/opt/homebrew/Cellar/python@3.10/3.10.9/Frameworks/Python.framework/Versions/3.10/lib/python3.10/http/client.py", line 1293, in _send_request
    self.putrequest(method, url, **skips)
  File "/opt/homebrew/Cellar/python@3.10/3.10.9/Frameworks/Python.framework/Versions/3.10/lib/python3.10/http/client.py", line 1127, in putrequest
    self._validate_path(url)
  File "/opt/homebrew/Cellar/python@3.10/3.10.9/Frameworks/Python.framework/Versions/3.10/lib/python3.10/http/client.py", line 1227, in _validate_path
    raise InvalidURL(f"URL can't contain control characters. {url!r} "
http.client.InvalidURL: URL can't contain control characters. '/VisualCrossingWebServices/rest/services/timeline/{city}/{data_interval_end}/{ds_add(data_interval_end, 7)}?unitGroup=metric&include=days&key={key}&contentType=csv' (found at least ' ')
[2023-02-10 17:56:14,598] {taskinstance.py:1395} INFO - Marking task as FAILED. dag_id=dados_climaticos, task_id=extrai_dados, execution_date=20230130T000000, start_date=20230210T175614, end_date=20230210T175614
[2023-02-10 17:56:14,601] {standard_task_runner.py:92} ERROR - Failed to execute job 127 for task extrai_dados (URL can't contain control characters. '/VisualCrossingWebServices/rest/services/timeline/{city}/{data_interval_end}/{ds_add(data_interval_end, 7)}?unitGroup=metric&include=days&key={key}&contentType=csv' (found at least ' '); 59058)
[2023-02-10 17:56:14,611] {local_task_job.py:156} INFO - Task exited with return code 1
[2023-02-10 17:56:14,620] {local_task_job.py:273} INFO - 0 downstream tasks scheduled from follow-on schedule check
