[2023-02-10 14:28:43,288] {taskinstance.py:1159} INFO - Dependencies all met for <TaskInstance: dados_climaticos.extrai_dados scheduled__2023-01-02T00:00:00+00:00 [queued]>
[2023-02-10 14:28:43,290] {taskinstance.py:1159} INFO - Dependencies all met for <TaskInstance: dados_climaticos.extrai_dados scheduled__2023-01-02T00:00:00+00:00 [queued]>
[2023-02-10 14:28:43,290] {taskinstance.py:1356} INFO - 
--------------------------------------------------------------------------------
[2023-02-10 14:28:43,290] {taskinstance.py:1357} INFO - Starting attempt 1 of 1
[2023-02-10 14:28:43,290] {taskinstance.py:1358} INFO - 
--------------------------------------------------------------------------------
[2023-02-10 14:28:43,294] {taskinstance.py:1377} INFO - Executing <Task(PythonOperator): extrai_dados> on 2023-01-02 00:00:00+00:00
[2023-02-10 14:28:43,296] {standard_task_runner.py:52} INFO - Started process 34567 to run task
[2023-02-10 14:28:43,299] {standard_task_runner.py:79} INFO - Running: ['airflow', 'tasks', 'run', 'dados_climaticos', 'extrai_dados', 'scheduled__2023-01-02T00:00:00+00:00', '--job-id', '56', '--raw', '--subdir', 'DAGS_FOLDER/dados_climaticos.py', '--cfg-path', '/var/folders/b_/44w2czd50d77jsslrsmc4_sc0000gn/T/tmplqb5d1_o', '--error-file', '/var/folders/b_/44w2czd50d77jsslrsmc4_sc0000gn/T/tmplsokl81a']
[2023-02-10 14:28:43,300] {standard_task_runner.py:80} INFO - Job 56: Subtask extrai_dados
[2023-02-10 14:28:43,314] {task_command.py:370} INFO - Running <TaskInstance: dados_climaticos.extrai_dados scheduled__2023-01-02T00:00:00+00:00 [running]> on host airdefrancilene.lan
[2023-02-10 14:28:43,323] {taskinstance.py:1889} ERROR - Task failed with exception
Traceback (most recent call last):
  File "/Users/francilenesilva/Documents/data-engineer/apache-airflow/orquestrando-pipeline1/data-pipeline/airflow-alura/venv/lib/python3.10/site-packages/airflow/models/taskinstance.py", line 1451, in _run_raw_task
    self._execute_task_with_callbacks(context, test_mode)
  File "/Users/francilenesilva/Documents/data-engineer/apache-airflow/orquestrando-pipeline1/data-pipeline/airflow-alura/venv/lib/python3.10/site-packages/airflow/models/taskinstance.py", line 1555, in _execute_task_with_callbacks
    task_orig = self.render_templates(context=context)
  File "/Users/francilenesilva/Documents/data-engineer/apache-airflow/orquestrando-pipeline1/data-pipeline/airflow-alura/venv/lib/python3.10/site-packages/airflow/models/taskinstance.py", line 2212, in render_templates
    rendered_task = self.task.render_template_fields(context)
  File "/Users/francilenesilva/Documents/data-engineer/apache-airflow/orquestrando-pipeline1/data-pipeline/airflow-alura/venv/lib/python3.10/site-packages/airflow/models/baseoperator.py", line 1185, in render_template_fields
    self._do_render_template_fields(self, self.template_fields, context, jinja_env, set())
  File "/Users/francilenesilva/Documents/data-engineer/apache-airflow/orquestrando-pipeline1/data-pipeline/airflow-alura/venv/lib/python3.10/site-packages/airflow/utils/session.py", line 71, in wrapper
    return func(*args, session=session, **kwargs)
  File "/Users/francilenesilva/Documents/data-engineer/apache-airflow/orquestrando-pipeline1/data-pipeline/airflow-alura/venv/lib/python3.10/site-packages/airflow/models/abstractoperator.py", line 344, in _do_render_template_fields
    rendered_content = self.render_template(
  File "/Users/francilenesilva/Documents/data-engineer/apache-airflow/orquestrando-pipeline1/data-pipeline/airflow-alura/venv/lib/python3.10/site-packages/airflow/models/abstractoperator.py", line 404, in render_template
    return {key: self.render_template(value, context, jinja_env) for key, value in value.items()}
  File "/Users/francilenesilva/Documents/data-engineer/apache-airflow/orquestrando-pipeline1/data-pipeline/airflow-alura/venv/lib/python3.10/site-packages/airflow/models/abstractoperator.py", line 404, in <dictcomp>
    return {key: self.render_template(value, context, jinja_env) for key, value in value.items()}
  File "/Users/francilenesilva/Documents/data-engineer/apache-airflow/orquestrando-pipeline1/data-pipeline/airflow-alura/venv/lib/python3.10/site-packages/airflow/models/abstractoperator.py", line 387, in render_template
    template = jinja_env.from_string(value)
  File "/Users/francilenesilva/Documents/data-engineer/apache-airflow/orquestrando-pipeline1/data-pipeline/airflow-alura/venv/lib/python3.10/site-packages/jinja2/environment.py", line 941, in from_string
    return cls.from_code(self, self.compile(source), globals, None)
  File "/Users/francilenesilva/Documents/data-engineer/apache-airflow/orquestrando-pipeline1/data-pipeline/airflow-alura/venv/lib/python3.10/site-packages/jinja2/environment.py", line 638, in compile
    self.handle_exception(source=source_hint)
  File "/Users/francilenesilva/Documents/data-engineer/apache-airflow/orquestrando-pipeline1/data-pipeline/airflow-alura/venv/lib/python3.10/site-packages/jinja2/environment.py", line 832, in handle_exception
    reraise(*rewrite_traceback_stack(source=source))
  File "/Users/francilenesilva/Documents/data-engineer/apache-airflow/orquestrando-pipeline1/data-pipeline/airflow-alura/venv/lib/python3.10/site-packages/jinja2/_compat.py", line 28, in reraise
    raise value.with_traceback(tb)
  File "<unknown>", line -1, in template
jinja2.exceptions.TemplateSyntaxError: unexpected char '"' at 29
[2023-02-10 14:28:43,326] {taskinstance.py:1395} INFO - Marking task as FAILED. dag_id=dados_climaticos, task_id=extrai_dados, execution_date=20230102T000000, start_date=20230210T142843, end_date=20230210T142843
[2023-02-10 14:28:43,328] {standard_task_runner.py:92} ERROR - Failed to execute job 56 for task extrai_dados (unexpected char '"' at 29; 34567)
[2023-02-10 14:28:43,361] {local_task_job.py:156} INFO - Task exited with return code 1
[2023-02-10 14:28:43,368] {local_task_job.py:273} INFO - 0 downstream tasks scheduled from follow-on schedule check
[2023-02-10 14:54:34,073] {taskinstance.py:1159} INFO - Dependencies all met for <TaskInstance: dados_climaticos.extrai_dados scheduled__2023-01-02T00:00:00+00:00 [queued]>
[2023-02-10 14:54:34,076] {taskinstance.py:1159} INFO - Dependencies all met for <TaskInstance: dados_climaticos.extrai_dados scheduled__2023-01-02T00:00:00+00:00 [queued]>
[2023-02-10 14:54:34,076] {taskinstance.py:1356} INFO - 
--------------------------------------------------------------------------------
[2023-02-10 14:54:34,076] {taskinstance.py:1357} INFO - Starting attempt 1 of 1
[2023-02-10 14:54:34,076] {taskinstance.py:1358} INFO - 
--------------------------------------------------------------------------------
[2023-02-10 14:54:34,080] {taskinstance.py:1377} INFO - Executing <Task(PythonOperator): extrai_dados> on 2023-01-02 00:00:00+00:00
[2023-02-10 14:54:34,082] {standard_task_runner.py:52} INFO - Started process 38223 to run task
[2023-02-10 14:54:34,085] {standard_task_runner.py:79} INFO - Running: ['airflow', 'tasks', 'run', 'dados_climaticos', 'extrai_dados', 'scheduled__2023-01-02T00:00:00+00:00', '--job-id', '66', '--raw', '--subdir', 'DAGS_FOLDER/dados_climaticos.py', '--cfg-path', '/var/folders/b_/44w2czd50d77jsslrsmc4_sc0000gn/T/tmp79jnvq6p', '--error-file', '/var/folders/b_/44w2czd50d77jsslrsmc4_sc0000gn/T/tmpfqu4in7x']
[2023-02-10 14:54:34,086] {standard_task_runner.py:80} INFO - Job 66: Subtask extrai_dados
[2023-02-10 14:54:34,102] {task_command.py:370} INFO - Running <TaskInstance: dados_climaticos.extrai_dados scheduled__2023-01-02T00:00:00+00:00 [running]> on host airdefrancilene.lan
[2023-02-10 14:54:34,116] {taskinstance.py:1889} ERROR - Task failed with exception
Traceback (most recent call last):
  File "/Users/francilenesilva/Documents/data-engineer/apache-airflow/orquestrando-pipeline1/data-pipeline/airflow-alura/venv/lib/python3.10/site-packages/airflow/models/taskinstance.py", line 1451, in _run_raw_task
    self._execute_task_with_callbacks(context, test_mode)
  File "/Users/francilenesilva/Documents/data-engineer/apache-airflow/orquestrando-pipeline1/data-pipeline/airflow-alura/venv/lib/python3.10/site-packages/airflow/models/taskinstance.py", line 1555, in _execute_task_with_callbacks
    task_orig = self.render_templates(context=context)
  File "/Users/francilenesilva/Documents/data-engineer/apache-airflow/orquestrando-pipeline1/data-pipeline/airflow-alura/venv/lib/python3.10/site-packages/airflow/models/taskinstance.py", line 2212, in render_templates
    rendered_task = self.task.render_template_fields(context)
  File "/Users/francilenesilva/Documents/data-engineer/apache-airflow/orquestrando-pipeline1/data-pipeline/airflow-alura/venv/lib/python3.10/site-packages/airflow/models/baseoperator.py", line 1185, in render_template_fields
    self._do_render_template_fields(self, self.template_fields, context, jinja_env, set())
  File "/Users/francilenesilva/Documents/data-engineer/apache-airflow/orquestrando-pipeline1/data-pipeline/airflow-alura/venv/lib/python3.10/site-packages/airflow/utils/session.py", line 71, in wrapper
    return func(*args, session=session, **kwargs)
  File "/Users/francilenesilva/Documents/data-engineer/apache-airflow/orquestrando-pipeline1/data-pipeline/airflow-alura/venv/lib/python3.10/site-packages/airflow/models/abstractoperator.py", line 344, in _do_render_template_fields
    rendered_content = self.render_template(
  File "/Users/francilenesilva/Documents/data-engineer/apache-airflow/orquestrando-pipeline1/data-pipeline/airflow-alura/venv/lib/python3.10/site-packages/airflow/models/abstractoperator.py", line 404, in render_template
    return {key: self.render_template(value, context, jinja_env) for key, value in value.items()}
  File "/Users/francilenesilva/Documents/data-engineer/apache-airflow/orquestrando-pipeline1/data-pipeline/airflow-alura/venv/lib/python3.10/site-packages/airflow/models/abstractoperator.py", line 404, in <dictcomp>
    return {key: self.render_template(value, context, jinja_env) for key, value in value.items()}
  File "/Users/francilenesilva/Documents/data-engineer/apache-airflow/orquestrando-pipeline1/data-pipeline/airflow-alura/venv/lib/python3.10/site-packages/airflow/models/abstractoperator.py", line 387, in render_template
    template = jinja_env.from_string(value)
  File "/Users/francilenesilva/Documents/data-engineer/apache-airflow/orquestrando-pipeline1/data-pipeline/airflow-alura/venv/lib/python3.10/site-packages/jinja2/environment.py", line 941, in from_string
    return cls.from_code(self, self.compile(source), globals, None)
  File "/Users/francilenesilva/Documents/data-engineer/apache-airflow/orquestrando-pipeline1/data-pipeline/airflow-alura/venv/lib/python3.10/site-packages/jinja2/environment.py", line 638, in compile
    self.handle_exception(source=source_hint)
  File "/Users/francilenesilva/Documents/data-engineer/apache-airflow/orquestrando-pipeline1/data-pipeline/airflow-alura/venv/lib/python3.10/site-packages/jinja2/environment.py", line 832, in handle_exception
    reraise(*rewrite_traceback_stack(source=source))
  File "/Users/francilenesilva/Documents/data-engineer/apache-airflow/orquestrando-pipeline1/data-pipeline/airflow-alura/venv/lib/python3.10/site-packages/jinja2/_compat.py", line 28, in reraise
    raise value.with_traceback(tb)
  File "<unknown>", line -1, in template
jinja2.exceptions.TemplateSyntaxError: unexpected char '"' at 29
[2023-02-10 14:54:34,120] {taskinstance.py:1395} INFO - Marking task as FAILED. dag_id=dados_climaticos, task_id=extrai_dados, execution_date=20230102T000000, start_date=20230210T145434, end_date=20230210T145434
[2023-02-10 14:54:34,123] {standard_task_runner.py:92} ERROR - Failed to execute job 66 for task extrai_dados (unexpected char '"' at 29; 38223)
[2023-02-10 14:54:34,146] {local_task_job.py:156} INFO - Task exited with return code 1
[2023-02-10 14:54:34,154] {local_task_job.py:273} INFO - 0 downstream tasks scheduled from follow-on schedule check
[2023-02-10 14:58:48,910] {taskinstance.py:1159} INFO - Dependencies all met for <TaskInstance: dados_climaticos.extrai_dados scheduled__2023-01-02T00:00:00+00:00 [queued]>
[2023-02-10 14:58:48,912] {taskinstance.py:1159} INFO - Dependencies all met for <TaskInstance: dados_climaticos.extrai_dados scheduled__2023-01-02T00:00:00+00:00 [queued]>
[2023-02-10 14:58:48,912] {taskinstance.py:1356} INFO - 
--------------------------------------------------------------------------------
[2023-02-10 14:58:48,912] {taskinstance.py:1357} INFO - Starting attempt 1 of 1
[2023-02-10 14:58:48,912] {taskinstance.py:1358} INFO - 
--------------------------------------------------------------------------------
[2023-02-10 14:58:48,916] {taskinstance.py:1377} INFO - Executing <Task(PythonOperator): extrai_dados> on 2023-01-02 00:00:00+00:00
[2023-02-10 14:58:48,918] {standard_task_runner.py:52} INFO - Started process 38879 to run task
[2023-02-10 14:58:48,920] {standard_task_runner.py:79} INFO - Running: ['airflow', 'tasks', 'run', 'dados_climaticos', 'extrai_dados', 'scheduled__2023-01-02T00:00:00+00:00', '--job-id', '68', '--raw', '--subdir', 'DAGS_FOLDER/dados_climaticos.py', '--cfg-path', '/var/folders/b_/44w2czd50d77jsslrsmc4_sc0000gn/T/tmp9_e0kbk2', '--error-file', '/var/folders/b_/44w2czd50d77jsslrsmc4_sc0000gn/T/tmpm0ovcpzj']
[2023-02-10 14:58:48,921] {standard_task_runner.py:80} INFO - Job 68: Subtask extrai_dados
[2023-02-10 14:58:48,937] {task_command.py:370} INFO - Running <TaskInstance: dados_climaticos.extrai_dados scheduled__2023-01-02T00:00:00+00:00 [running]> on host airdefrancilene.lan
[2023-02-10 14:58:48,953] {taskinstance.py:1569} INFO - Exporting the following env vars:
AIRFLOW_CTX_DAG_OWNER=airflow
AIRFLOW_CTX_DAG_ID=dados_climaticos
AIRFLOW_CTX_TASK_ID=extrai_dados
AIRFLOW_CTX_EXECUTION_DATE=2023-01-02T00:00:00+00:00
AIRFLOW_CTX_TRY_NUMBER=1
AIRFLOW_CTX_DAG_RUN_ID=scheduled__2023-01-02T00:00:00+00:00
[2023-02-10 14:58:48,954] {taskinstance.py:1889} ERROR - Task failed with exception
Traceback (most recent call last):
  File "/Users/francilenesilva/Documents/data-engineer/apache-airflow/orquestrando-pipeline1/data-pipeline/airflow-alura/venv/lib/python3.10/site-packages/airflow/operators/python.py", line 171, in execute
    return_value = self.execute_callable()
  File "/Users/francilenesilva/Documents/data-engineer/apache-airflow/orquestrando-pipeline1/data-pipeline/airflow-alura/venv/lib/python3.10/site-packages/airflow/operators/python.py", line 189, in execute_callable
    return self.python_callable(*self.op_args, **self.op_kwargs)
  File "/Users/francilenesilva/Documents/data-engineer/apache-airflow/orquestrando-pipeline1/data-pipeline/airflow-alura/dags/dados_climaticos.py", line 33, in extrai_dados
    f'{city}/{data_interval_end}/{ds_add(data_interval_end, 7)}?unitGroup=metric&include=days&key={key}&contentType=csv')
  File "/Users/francilenesilva/Documents/data-engineer/apache-airflow/orquestrando-pipeline1/data-pipeline/airflow-alura/venv/lib/python3.10/site-packages/airflow/macros/__init__.py", line 44, in ds_add
    dt = datetime.strptime(str(ds), "%Y-%m-%d") + timedelta(days=days)
  File "/opt/homebrew/Cellar/python@3.10/3.10.9/Frameworks/Python.framework/Versions/3.10/lib/python3.10/_strptime.py", line 568, in _strptime_datetime
    tt, fraction, gmtoff_fraction = _strptime(data_string, format)
  File "/opt/homebrew/Cellar/python@3.10/3.10.9/Frameworks/Python.framework/Versions/3.10/lib/python3.10/_strptime.py", line 352, in _strptime
    raise ValueError("unconverted data remains: %s" %
ValueError: unconverted data remains: T00:00:00+00:00
[2023-02-10 14:58:48,956] {taskinstance.py:1395} INFO - Marking task as FAILED. dag_id=dados_climaticos, task_id=extrai_dados, execution_date=20230102T000000, start_date=20230210T145848, end_date=20230210T145848
[2023-02-10 14:58:48,959] {standard_task_runner.py:92} ERROR - Failed to execute job 68 for task extrai_dados (unconverted data remains: T00:00:00+00:00; 38879)
[2023-02-10 14:58:48,982] {local_task_job.py:156} INFO - Task exited with return code 1
[2023-02-10 14:58:48,989] {local_task_job.py:273} INFO - 0 downstream tasks scheduled from follow-on schedule check
[2023-02-10 17:29:21,502] {taskinstance.py:1159} INFO - Dependencies all met for <TaskInstance: dados_climaticos.extrai_dados scheduled__2023-01-02T00:00:00+00:00 [queued]>
[2023-02-10 17:29:21,505] {taskinstance.py:1159} INFO - Dependencies all met for <TaskInstance: dados_climaticos.extrai_dados scheduled__2023-01-02T00:00:00+00:00 [queued]>
[2023-02-10 17:29:21,505] {taskinstance.py:1356} INFO - 
--------------------------------------------------------------------------------
[2023-02-10 17:29:21,505] {taskinstance.py:1357} INFO - Starting attempt 1 of 1
[2023-02-10 17:29:21,505] {taskinstance.py:1358} INFO - 
--------------------------------------------------------------------------------
[2023-02-10 17:29:21,508] {taskinstance.py:1377} INFO - Executing <Task(PythonOperator): extrai_dados> on 2023-01-02 00:00:00+00:00
[2023-02-10 17:29:21,510] {standard_task_runner.py:52} INFO - Started process 55348 to run task
[2023-02-10 17:29:21,512] {standard_task_runner.py:79} INFO - Running: ['airflow', 'tasks', 'run', 'dados_climaticos', 'extrai_dados', 'scheduled__2023-01-02T00:00:00+00:00', '--job-id', '106', '--raw', '--subdir', 'DAGS_FOLDER/dados_climaticos.py', '--cfg-path', '/var/folders/b_/44w2czd50d77jsslrsmc4_sc0000gn/T/tmpb8d0n4oy', '--error-file', '/var/folders/b_/44w2czd50d77jsslrsmc4_sc0000gn/T/tmpnp038xkq']
[2023-02-10 17:29:21,513] {standard_task_runner.py:80} INFO - Job 106: Subtask extrai_dados
[2023-02-10 17:29:21,529] {task_command.py:370} INFO - Running <TaskInstance: dados_climaticos.extrai_dados scheduled__2023-01-02T00:00:00+00:00 [running]> on host airdefrancilene.lan
[2023-02-10 17:29:21,545] {taskinstance.py:1569} INFO - Exporting the following env vars:
AIRFLOW_CTX_DAG_OWNER=airflow
AIRFLOW_CTX_DAG_ID=dados_climaticos
AIRFLOW_CTX_TASK_ID=extrai_dados
AIRFLOW_CTX_EXECUTION_DATE=2023-01-02T00:00:00+00:00
AIRFLOW_CTX_TRY_NUMBER=1
AIRFLOW_CTX_DAG_RUN_ID=scheduled__2023-01-02T00:00:00+00:00
[2023-02-10 17:29:21,665] {local_task_job.py:156} INFO - Task exited with return code Negsignal.SIGSEGV
[2023-02-10 17:29:21,671] {taskinstance.py:1395} INFO - Marking task as FAILED. dag_id=dados_climaticos, task_id=extrai_dados, execution_date=20230102T000000, start_date=20230210T172921, end_date=20230210T172921
[2023-02-10 17:29:21,677] {local_task_job.py:273} INFO - 0 downstream tasks scheduled from follow-on schedule check
[2023-02-10 17:33:21,942] {taskinstance.py:1159} INFO - Dependencies all met for <TaskInstance: dados_climaticos.extrai_dados scheduled__2023-01-02T00:00:00+00:00 [queued]>
[2023-02-10 17:33:21,944] {taskinstance.py:1159} INFO - Dependencies all met for <TaskInstance: dados_climaticos.extrai_dados scheduled__2023-01-02T00:00:00+00:00 [queued]>
[2023-02-10 17:33:21,944] {taskinstance.py:1356} INFO - 
--------------------------------------------------------------------------------
[2023-02-10 17:33:21,944] {taskinstance.py:1357} INFO - Starting attempt 1 of 1
[2023-02-10 17:33:21,944] {taskinstance.py:1358} INFO - 
--------------------------------------------------------------------------------
[2023-02-10 17:33:21,948] {taskinstance.py:1377} INFO - Executing <Task(PythonOperator): extrai_dados> on 2023-01-02 00:00:00+00:00
[2023-02-10 17:33:21,950] {standard_task_runner.py:52} INFO - Started process 55923 to run task
[2023-02-10 17:33:21,953] {standard_task_runner.py:79} INFO - Running: ['airflow', 'tasks', 'run', 'dados_climaticos', 'extrai_dados', 'scheduled__2023-01-02T00:00:00+00:00', '--job-id', '122', '--raw', '--subdir', 'DAGS_FOLDER/dados_climaticos.py', '--cfg-path', '/var/folders/b_/44w2czd50d77jsslrsmc4_sc0000gn/T/tmp_urwkjoc', '--error-file', '/var/folders/b_/44w2czd50d77jsslrsmc4_sc0000gn/T/tmpmiyqbbav']
[2023-02-10 17:33:21,953] {standard_task_runner.py:80} INFO - Job 122: Subtask extrai_dados
[2023-02-10 17:33:21,969] {task_command.py:370} INFO - Running <TaskInstance: dados_climaticos.extrai_dados scheduled__2023-01-02T00:00:00+00:00 [running]> on host airdefrancilene.lan
[2023-02-10 17:33:21,990] {taskinstance.py:1569} INFO - Exporting the following env vars:
AIRFLOW_CTX_DAG_OWNER=airflow
AIRFLOW_CTX_DAG_ID=dados_climaticos
AIRFLOW_CTX_TASK_ID=extrai_dados
AIRFLOW_CTX_EXECUTION_DATE=2023-01-02T00:00:00+00:00
AIRFLOW_CTX_TRY_NUMBER=1
AIRFLOW_CTX_DAG_RUN_ID=scheduled__2023-01-02T00:00:00+00:00
[2023-02-10 17:33:22,100] {local_task_job.py:156} INFO - Task exited with return code Negsignal.SIGSEGV
[2023-02-10 17:33:22,106] {taskinstance.py:1395} INFO - Marking task as FAILED. dag_id=dados_climaticos, task_id=extrai_dados, execution_date=20230102T000000, start_date=20230210T173321, end_date=20230210T173322
[2023-02-10 17:33:22,112] {local_task_job.py:273} INFO - 0 downstream tasks scheduled from follow-on schedule check
